[Mon Feb 01 05:30:02.247281 2021] [wsgi:error] [pid 15161:tid 140505384261376] [remote 104.195.132.229:61136] Internal Server Error: /handlePay
[Mon Feb 01 05:30:02.247392 2021] [wsgi:error] [pid 15161:tid 140505384261376] [remote 104.195.132.229:61136] Traceback (most recent call last):
[Mon Feb 01 05:30:02.247396 2021] [wsgi:error] [pid 15161:tid 140505384261376] [remote 104.195.132.229:61136]   File "/usr/local/lib/python3.6/dist-packages/django/core/handlers/exception.py", line 47, in inner
[Mon Feb 01 05:30:02.247399 2021] [wsgi:error] [pid 15161:tid 140505384261376] [remote 104.195.132.229:61136]     response = get_response(request)
[Mon Feb 01 05:30:02.247403 2021] [wsgi:error] [pid 15161:tid 140505384261376] [remote 104.195.132.229:61136]   File "/usr/local/lib/python3.6/dist-packages/django/core/handlers/base.py", line 179, in _get_response
[Mon Feb 01 05:30:02.247407 2021] [wsgi:error] [pid 15161:tid 140505384261376] [remote 104.195.132.229:61136]     response = wrapped_callback(request, *callback_args, **callback_kwargs)
[Mon Feb 01 05:30:02.247410 2021] [wsgi:error] [pid 15161:tid 140505384261376] [remote 104.195.132.229:61136]   File "/usr/local/lib/python3.6/dist-packages/django/views/decorators/csrf.py", line 54, in wrapped_view
[Mon Feb 01 05:30:02.247413 2021] [wsgi:error] [pid 15161:tid 140505384261376] [remote 104.195.132.229:61136]     return view_func(*args, **kwargs)
[Mon Feb 01 05:30:02.247416 2021] [wsgi:error] [pid 15161:tid 140505384261376] [remote 104.195.132.229:61136]   File "/var/www/HonestyNetwork/main/views.py", line 59, in handlePay
[Mon Feb 01 05:30:02.247418 2021] [wsgi:error] [pid 15161:tid 140505384261376] [remote 104.195.132.229:61136]     error_on_requires_action = True,
[Mon Feb 01 05:30:02.247422 2021] [wsgi:error] [pid 15161:tid 140505384261376] [remote 104.195.132.229:61136]   File "/usr/local/lib/python3.6/dist-packages/stripe/api_resources/abstract/createable_api_resource.py", line 22, in create
[Mon Feb 01 05:30:02.247425 2021] [wsgi:error] [pid 15161:tid 140505384261376] [remote 104.195.132.229:61136]     response, api_key = requestor.request("post", url, params, headers)
[Mon Feb 01 05:30:02.247428 2021] [wsgi:error] [pid 15161:tid 140505384261376] [remote 104.195.132.229:61136]   File "/usr/local/lib/python3.6/dist-packages/stripe/api_requestor.py", line 122, in request
[Mon Feb 01 05:30:02.247431 2021] [wsgi:error] [pid 15161:tid 140505384261376] [remote 104.195.132.229:61136]     resp = self.interpret_response(rbody, rcode, rheaders)
[Mon Feb 01 05:30:02.247433 2021] [wsgi:error] [pid 15161:tid 140505384261376] [remote 104.195.132.229:61136]   File "/usr/local/lib/python3.6/dist-packages/stripe/api_requestor.py", line 373, in interpret_response
[Mon Feb 01 05:30:02.247436 2021] [wsgi:error] [pid 15161:tid 140505384261376] [remote 104.195.132.229:61136]     self.handle_error_response(rbody, rcode, resp.data, rheaders)
[Mon Feb 01 05:30:02.247439 2021] [wsgi:error] [pid 15161:tid 140505384261376] [remote 104.195.132.229:61136]   File "/usr/local/lib/python3.6/dist-packages/stripe/api_requestor.py", line 152, in handle_error_response
[Mon Feb 01 05:30:02.247442 2021] [wsgi:error] [pid 15161:tid 140505384261376] [remote 104.195.132.229:61136]     raise err
[Mon Feb 01 05:30:02.247447 2021] [wsgi:error] [pid 15161:tid 140505384261376] [remote 104.195.132.229:61136] stripe.error.InvalidRequestError: Request req_R2TSrraKj3ibBI: This value must be greater than or equal to 1.
[Mon Feb 01 05:30:02.247453 2021] [wsgi:error] [pid 15161:tid 140505384261376] [remote 104.195.132.229:61136] 
[Mon Feb 01 05:30:28.307002 2021] [wsgi:error] [pid 15162:tid 140505384261376] [remote 104.195.132.229:61150] <QuerySet [<SetModels: FWHZ16IC8DL564HG1XH0>, <SetModels: 47H5R6R1450YIEZUEWJ0>]>
[Mon Feb 01 05:30:39.665705 2021] [wsgi:error] [pid 15161:tid 140505384261376] [remote 104.195.132.229:61158] Internal Server Error: /handlePay
[Mon Feb 01 05:30:39.665752 2021] [wsgi:error] [pid 15161:tid 140505384261376] [remote 104.195.132.229:61158] Traceback (most recent call last):
[Mon Feb 01 05:30:39.665756 2021] [wsgi:error] [pid 15161:tid 140505384261376] [remote 104.195.132.229:61158]   File "/usr/local/lib/python3.6/dist-packages/django/core/handlers/exception.py", line 47, in inner
[Mon Feb 01 05:30:39.665773 2021] [wsgi:error] [pid 15161:tid 140505384261376] [remote 104.195.132.229:61158]     response = get_response(request)
[Mon Feb 01 05:30:39.665776 2021] [wsgi:error] [pid 15161:tid 140505384261376] [remote 104.195.132.229:61158]   File "/usr/local/lib/python3.6/dist-packages/django/core/handlers/base.py", line 179, in _get_response
[Mon Feb 01 05:30:39.665780 2021] [wsgi:error] [pid 15161:tid 140505384261376] [remote 104.195.132.229:61158]     response = wrapped_callback(request, *callback_args, **callback_kwargs)
[Mon Feb 01 05:30:39.665783 2021] [wsgi:error] [pid 15161:tid 140505384261376] [remote 104.195.132.229:61158]   File "/usr/local/lib/python3.6/dist-packages/django/views/decorators/csrf.py", line 54, in wrapped_view
[Mon Feb 01 05:30:39.665786 2021] [wsgi:error] [pid 15161:tid 140505384261376] [remote 104.195.132.229:61158]     return view_func(*args, **kwargs)
[Mon Feb 01 05:30:39.665789 2021] [wsgi:error] [pid 15161:tid 140505384261376] [remote 104.195.132.229:61158]   File "/var/www/HonestyNetwork/main/views.py", line 59, in handlePay
[Mon Feb 01 05:30:39.665792 2021] [wsgi:error] [pid 15161:tid 140505384261376] [remote 104.195.132.229:61158]     error_on_requires_action = True,
[Mon Feb 01 05:30:39.665795 2021] [wsgi:error] [pid 15161:tid 140505384261376] [remote 104.195.132.229:61158]   File "/usr/local/lib/python3.6/dist-packages/stripe/api_resources/abstract/createable_api_resource.py", line 22, in create
[Mon Feb 01 05:30:39.665798 2021] [wsgi:error] [pid 15161:tid 140505384261376] [remote 104.195.132.229:61158]     response, api_key = requestor.request("post", url, params, headers)
[Mon Feb 01 05:30:39.665801 2021] [wsgi:error] [pid 15161:tid 140505384261376] [remote 104.195.132.229:61158]   File "/usr/local/lib/python3.6/dist-packages/stripe/api_requestor.py", line 122, in request
[Mon Feb 01 05:30:39.665804 2021] [wsgi:error] [pid 15161:tid 140505384261376] [remote 104.195.132.229:61158]     resp = self.interpret_response(rbody, rcode, rheaders)
[Mon Feb 01 05:30:39.665807 2021] [wsgi:error] [pid 15161:tid 140505384261376] [remote 104.195.132.229:61158]   File "/usr/local/lib/python3.6/dist-packages/stripe/api_requestor.py", line 373, in interpret_response
[Mon Feb 01 05:30:39.665810 2021] [wsgi:error] [pid 15161:tid 140505384261376] [remote 104.195.132.229:61158]     self.handle_error_response(rbody, rcode, resp.data, rheaders)
[Mon Feb 01 05:30:39.665813 2021] [wsgi:error] [pid 15161:tid 140505384261376] [remote 104.195.132.229:61158]   File "/usr/local/lib/python3.6/dist-packages/stripe/api_requestor.py", line 152, in handle_error_response
[Mon Feb 01 05:30:39.665815 2021] [wsgi:error] [pid 15161:tid 140505384261376] [remote 104.195.132.229:61158]     raise err
[Mon Feb 01 05:30:39.665820 2021] [wsgi:error] [pid 15161:tid 140505384261376] [remote 104.195.132.229:61158] stripe.error.InvalidRequestError: Request req_P0Tu9ifFb029PC: This value must be greater than or equal to 1.
[Mon Feb 01 05:30:39.665827 2021] [wsgi:error] [pid 15161:tid 140505384261376] [remote 104.195.132.229:61158] 
[Mon Feb 01 05:33:01.032602 2021] [wsgi:error] [pid 15161:tid 140505182836480] [remote 104.195.132.229:61237] <QuerySet [<SetModels: FWHZ16IC8DL564HG1XH0>, <SetModels: 47H5R6R1450YIEZUEWJ0>]>
[Mon Feb 01 05:33:17.085756 2021] [wsgi:error] [pid 15162:tid 140505384261376] [remote 104.195.132.229:61247] <QuerySet [<SetModels: FWHZ16IC8DL564HG1XH0>, <SetModels: 47H5R6R1450YIEZUEWJ0>]>
[Mon Feb 01 05:33:36.457128 2021] [wsgi:error] [pid 15161:tid 140505182836480] [remote 104.195.132.229:61253] <QuerySet [<SetModels: FWHZ16IC8DL564HG1XH0>, <SetModels: 47H5R6R1450YIEZUEWJ0>]>
[Mon Feb 01 05:34:37.414628 2021] [wsgi:error] [pid 15161:tid 140505182836480] [remote 104.195.132.229:61313] <QuerySet [<SetModels: FWHZ16IC8DL564HG1XH0>, <SetModels: 47H5R6R1450YIEZUEWJ0>]>
[Mon Feb 01 05:34:39.815614 2021] [wsgi:error] [pid 15161:tid 140505384261376] [remote 104.195.132.229:61313] Internal Server Error: /makePayment
[Mon Feb 01 05:34:39.815687 2021] [wsgi:error] [pid 15161:tid 140505384261376] [remote 104.195.132.229:61313] Traceback (most recent call last):
[Mon Feb 01 05:34:39.815694 2021] [wsgi:error] [pid 15161:tid 140505384261376] [remote 104.195.132.229:61313]   File "/usr/local/lib/python3.6/dist-packages/django/core/handlers/exception.py", line 47, in inner
[Mon Feb 01 05:34:39.815698 2021] [wsgi:error] [pid 15161:tid 140505384261376] [remote 104.195.132.229:61313]     response = get_response(request)
[Mon Feb 01 05:34:39.815703 2021] [wsgi:error] [pid 15161:tid 140505384261376] [remote 104.195.132.229:61313]   File "/usr/local/lib/python3.6/dist-packages/django/core/handlers/base.py", line 179, in _get_response
[Mon Feb 01 05:34:39.815707 2021] [wsgi:error] [pid 15161:tid 140505384261376] [remote 104.195.132.229:61313]     response = wrapped_callback(request, *callback_args, **callback_kwargs)
[Mon Feb 01 05:34:39.815711 2021] [wsgi:error] [pid 15161:tid 140505384261376] [remote 104.195.132.229:61313]   File "/usr/local/lib/python3.6/dist-packages/django/views/decorators/csrf.py", line 54, in wrapped_view
[Mon Feb 01 05:34:39.815714 2021] [wsgi:error] [pid 15161:tid 140505384261376] [remote 104.195.132.229:61313]     return view_func(*args, **kwargs)
[Mon Feb 01 05:34:39.815718 2021] [wsgi:error] [pid 15161:tid 140505384261376] [remote 104.195.132.229:61313]   File "/var/www/HonestyNetwork/main/views.py", line 40, in makePayment
[Mon Feb 01 05:34:39.815722 2021] [wsgi:error] [pid 15161:tid 140505384261376] [remote 104.195.132.229:61313]     currency = 'cad')
[Mon Feb 01 05:34:39.815725 2021] [wsgi:error] [pid 15161:tid 140505384261376] [remote 104.195.132.229:61313]   File "/usr/local/lib/python3.6/dist-packages/stripe/api_resources/abstract/createable_api_resource.py", line 22, in create
[Mon Feb 01 05:34:39.815729 2021] [wsgi:error] [pid 15161:tid 140505384261376] [remote 104.195.132.229:61313]     response, api_key = requestor.request("post", url, params, headers)
[Mon Feb 01 05:34:39.815732 2021] [wsgi:error] [pid 15161:tid 140505384261376] [remote 104.195.132.229:61313]   File "/usr/local/lib/python3.6/dist-packages/stripe/api_requestor.py", line 122, in request
[Mon Feb 01 05:34:39.815736 2021] [wsgi:error] [pid 15161:tid 140505384261376] [remote 104.195.132.229:61313]     resp = self.interpret_response(rbody, rcode, rheaders)
[Mon Feb 01 05:34:39.815739 2021] [wsgi:error] [pid 15161:tid 140505384261376] [remote 104.195.132.229:61313]   File "/usr/local/lib/python3.6/dist-packages/stripe/api_requestor.py", line 373, in interpret_response
[Mon Feb 01 05:34:39.815742 2021] [wsgi:error] [pid 15161:tid 140505384261376] [remote 104.195.132.229:61313]     self.handle_error_response(rbody, rcode, resp.data, rheaders)
[Mon Feb 01 05:34:39.815746 2021] [wsgi:error] [pid 15161:tid 140505384261376] [remote 104.195.132.229:61313]   File "/usr/local/lib/python3.6/dist-packages/stripe/api_requestor.py", line 152, in handle_error_response
[Mon Feb 01 05:34:39.815749 2021] [wsgi:error] [pid 15161:tid 140505384261376] [remote 104.195.132.229:61313]     raise err
[Mon Feb 01 05:34:39.815754 2021] [wsgi:error] [pid 15161:tid 140505384261376] [remote 104.195.132.229:61313] stripe.error.InvalidRequestError: Request req_IHISW7UVAELFin: Amount must be at least $0.50 cad
[Mon Feb 01 05:34:39.815762 2021] [wsgi:error] [pid 15161:tid 140505384261376] [remote 104.195.132.229:61313] 
[Mon Feb 01 05:37:02.884071 2021] [wsgi:error] [pid 15161:tid 140505384261376] [remote 104.195.132.229:61397] <QuerySet [<SetModels: FWHZ16IC8DL564HG1XH0>, <SetModels: 47H5R6R1450YIEZUEWJ0>]>
[Mon Feb 01 05:54:08.782730 2021] [wsgi:error] [pid 15161:tid 140505384261376] [remote 104.195.132.229:62003] <QuerySet [<SetModels: FWHZ16IC8DL564HG1XH0>, <SetModels: 47H5R6R1450YIEZUEWJ0>]>
[Mon Feb 01 05:55:19.174067 2021] [wsgi:error] [pid 15161:tid 140505384261376] [remote 104.195.132.229:62041] <QuerySet [<SetModels: FWHZ16IC8DL564HG1XH0>, <SetModels: 47H5R6R1450YIEZUEWJ0>]>
[Mon Feb 01 05:55:21.226598 2021] [wsgi:error] [pid 15162:tid 140505384261376] [remote 104.195.132.229:62041] <QuerySet [<SetModels: FWHZ16IC8DL564HG1XH0>, <SetModels: 47H5R6R1450YIEZUEWJ0>]>
[Mon Feb 01 05:55:21.803788 2021] [wsgi:error] [pid 15161:tid 140505182836480] [remote 104.195.132.229:62041] ['188XRW2LYAFG4HHWRWWT']
[Mon Feb 01 05:55:21.803835 2021] [wsgi:error] [pid 15161:tid 140505182836480] [remote 104.195.132.229:62041] ['FWHZ16IC8DL564HG1XH0', '47H5R6R1450YIEZUEWJ0']
[Mon Feb 01 05:56:07.655713 2021] [wsgi:error] [pid 15162:tid 140505384261376] [remote 104.195.132.229:62068] <QuerySet [<SetModels: FWHZ16IC8DL564HG1XH0>, <SetModels: 188XRW2LYAFG4HHWRWWT>, <SetModels: 47H5R6R1450YIEZUEWJ0>]>
[Mon Feb 01 06:01:18.919169 2021] [wsgi:error] [pid 15161:tid 140505182836480] [remote 104.195.132.229:62266] <QuerySet [<SetModels: FWHZ16IC8DL564HG1XH0>, <SetModels: 188XRW2LYAFG4HHWRWWT>, <SetModels: 47H5R6R1450YIEZUEWJ0>]>
[Mon Feb 01 06:01:23.171178 2021] [wsgi:error] [pid 15162:tid 140505384261376] [remote 104.195.132.229:62266] <QuerySet [<SetModels: FWHZ16IC8DL564HG1XH0>, <SetModels: 188XRW2LYAFG4HHWRWWT>, <SetModels: 47H5R6R1450YIEZUEWJ0>]>
[Mon Feb 01 06:02:35.244064 2021] [wsgi:error] [pid 15161:tid 140505384261376] [remote 104.195.132.229:62311] <QuerySet [<SetModels: FWHZ16IC8DL564HG1XH0>, <SetModels: 188XRW2LYAFG4HHWRWWT>, <SetModels: 47H5R6R1450YIEZUEWJ0>]>
[Mon Feb 01 06:02:58.338534 2021] [wsgi:error] [pid 15162:tid 140505308727040] [remote 104.195.132.229:62327] <QuerySet [<SetModels: FWHZ16IC8DL564HG1XH0>, <SetModels: 188XRW2LYAFG4HHWRWWT>, <SetModels: 47H5R6R1450YIEZUEWJ0>]>
[Mon Feb 01 06:03:28.899090 2021] [wsgi:error] [pid 15162:tid 140505384261376] [remote 104.195.132.229:62349] <QuerySet [<SetModels: FWHZ16IC8DL564HG1XH0>, <SetModels: 188XRW2LYAFG4HHWRWWT>, <SetModels: 47H5R6R1450YIEZUEWJ0>]>
Exception ignored in: <bound method BaseEventLoop.__del__ of <_UnixSelectorEventLoop running=False closed=False debug=False>>
Traceback (most recent call last):
  File "/usr/lib/python3.6/asyncio/base_events.py", line 526, in __del__
NameError: name 'ResourceWarning' is not defined
Exception ignored in: <bound method BaseEventLoop.__del__ of <_UnixSelectorEventLoop running=False closed=False debug=False>>
Traceback (most recent call last):
  File "/usr/lib/python3.6/asyncio/base_events.py", line 526, in __del__
NameError: name 'ResourceWarning' is not defined
[Mon Feb 01 06:43:45.335999 2021] [wsgi:error] [pid 16773:tid 140505384261376] [client 157.245.176.143:40584] Invalid Content-Length header value of '18446744073709551615' was supplied.: /var/www/HonestyNetwork/HonestyNetwork/wsgi.py
[Mon Feb 01 12:18:51.265325 2021] [wsgi:error] [pid 16771:tid 140505208014592] [remote 198.199.110.83:56810] Not Found: /owa/auth/logon.aspx
[Mon Feb 01 16:06:33.943811 2021] [wsgi:error] [pid 16771:tid 140505208014592] [remote 40.121.23.173:61005] Not Found: /.env
[Mon Feb 01 16:06:34.147795 2021] [wsgi:error] [pid 16770:tid 140505384261376] [remote 40.121.23.173:61027] Forbidden (Referer checking failed - no Referer.): /
[Mon Feb 01 17:07:56.469239 2021] [wsgi:error] [pid 16770:tid 140505182836480] [remote 104.195.132.229:65247] <QuerySet [<SetModels: FWHZ16IC8DL564HG1XH0>, <SetModels: 188XRW2LYAFG4HHWRWWT>, <SetModels: 47H5R6R1450YIEZUEWJ0>]>
Exception ignored in: <bound method BaseEventLoop.__del__ of <_UnixSelectorEventLoop running=False closed=False debug=False>>
Traceback (most recent call last):
  File "/usr/lib/python3.6/asyncio/base_events.py", line 526, in __del__
NameError: name 'ResourceWarning' is not defined
Exception ignored in: <bound method BaseEventLoop.__del__ of <_UnixSelectorEventLoop running=False closed=False debug=False>>
Traceback (most recent call last):
  File "/usr/lib/python3.6/asyncio/base_events.py", line 526, in __del__
NameError: name 'ResourceWarning' is not defined
[Mon Feb 01 18:48:44.181393 2021] [ssl:warn] [pid 717:tid 140505513569216] AH01909: honestynetwork.ca:443:0 server certificate does NOT include an ID which matches the server name
[Mon Feb 01 18:52:03.628593 2021] [ssl:warn] [pid 717:tid 140505513569216] AH01909: honestynetwork.ca:443:0 server certificate does NOT include an ID which matches the server name
[Mon Feb 01 18:52:42.660985 2021] [ssl:warn] [pid 717:tid 140505513569216] AH01909: honestynetwork.ca:443:0 server certificate does NOT include an ID which matches the server name
[Mon Feb 01 18:54:18.634894 2021] [ssl:warn] [pid 717:tid 140505513569216] AH01909: honestynetwork.ca:443:0 server certificate does NOT include an ID which matches the server name
Exception ignored in: <bound method BaseEventLoop.__del__ of <_UnixSelectorEventLoop running=False closed=False debug=False>>
Traceback (most recent call last):
  File "/usr/lib/python3.6/asyncio/base_events.py", line 526, in __del__
NameError: name 'ResourceWarning' is not defined
[Mon Feb 01 18:57:48.863507 2021] [ssl:warn] [pid 717:tid 140505513569216] AH01909: honestynetwork.ca:443:0 server certificate does NOT include an ID which matches the server name
[Mon Feb 01 18:58:01.484981 2021] [ssl:warn] [pid 717:tid 140505513569216] AH01909: honestynetwork.ca:443:0 server certificate does NOT include an ID which matches the server name
[Mon Feb 01 18:58:08.045032 2021] [ssl:warn] [pid 717:tid 140505513569216] AH01909: honestynetwork.ca:443:0 server certificate does NOT include an ID which matches the server name
Exception ignored in: <bound method BaseEventLoop.__del__ of <_UnixSelectorEventLoop running=False closed=False debug=False>>
Traceback (most recent call last):
  File "/usr/lib/python3.6/asyncio/base_events.py", line 526, in __del__
NameError: name 'ResourceWarning' is not defined
Exception ignored in: <bound method BaseEventLoop.__del__ of <_UnixSelectorEventLoop running=False closed=False debug=False>>
Traceback (most recent call last):
  File "/usr/lib/python3.6/asyncio/base_events.py", line 526, in __del__
NameError: name 'ResourceWarning' is not defined
Exception ignored in: <bound method BaseEventLoop.__del__ of <_UnixSelectorEventLoop running=False closed=False debug=False>>
Traceback (most recent call last):
  File "/usr/lib/python3.6/asyncio/base_events.py", line 526, in __del__
NameError: name 'ResourceWarning' is not defined
Exception ignored in: <bound method BaseEventLoop.__del__ of <_UnixSelectorEventLoop running=False closed=False debug=False>>
Traceback (most recent call last):
  File "/usr/lib/python3.6/asyncio/base_events.py", line 526, in __del__
NameError: name 'ResourceWarning' is not defined
Exception ignored in: <bound method BaseEventLoop.__del__ of <_UnixSelectorEventLoop running=False closed=False debug=False>>
Traceback (most recent call last):
  File "/usr/lib/python3.6/asyncio/base_events.py", line 526, in __del__
NameError: name 'ResourceWarning' is not defined
Exception ignored in: <bound method BaseEventLoop.__del__ of <_UnixSelectorEventLoop running=False closed=False debug=False>>
Traceback (most recent call last):
  File "/usr/lib/python3.6/asyncio/base_events.py", line 526, in __del__
NameError: name 'ResourceWarning' is not defined
[Mon Feb 01 19:26:33.225540 2021] [wsgi:error] [pid 24147:tid 140505224800000] [remote 104.195.132.229:53297] <QuerySet []>
[Mon Feb 01 19:26:40.201562 2021] [wsgi:error] [pid 24148:tid 140505384261376] [remote 104.195.132.229:53300] <QuerySet []>
[Mon Feb 01 19:26:42.021852 2021] [wsgi:error] [pid 24147:tid 140505384261376] [remote 104.195.132.229:53300] []
[Mon Feb 01 19:26:42.021910 2021] [wsgi:error] [pid 24147:tid 140505384261376] [remote 104.195.132.229:53300] []
[Mon Feb 01 21:48:39.323035 2021] [wsgi:error] [pid 24148:tid 140505384261376] [remote 45.155.205.108:42356] Not Found: /vendor/phpunit/phpunit/src/Util/PHP/eval-stdin.php
[Mon Feb 01 21:48:39.321186 2021] [wsgi:error] [pid 24147:tid 140505384261376] [remote 45.155.205.108:42348] Not Found: /api/jsonws/invoke
[Mon Feb 01 21:48:41.067229 2021] [wsgi:error] [pid 24148:tid 140505182836480] [remote 45.155.205.108:38560] Not Found: /index.php
[Mon Feb 01 21:48:41.121677 2021] [wsgi:error] [pid 24147:tid 140505224800000] [remote 45.155.205.108:36552] Not Found: /vendor/phpunit/phpunit/src/Util/PHP/eval-stdin.php
[Mon Feb 01 21:48:46.934632 2021] [wsgi:error] [pid 24147:tid 140505384261376] [remote 45.155.205.108:44810] Not Found: /mifs/.;/services/LogService
[Mon Feb 01 21:48:47.570282 2021] [wsgi:error] [pid 24148:tid 140505182836480] [remote 45.155.205.108:50250] Not Found: /wp-content/plugins/wp-file-manager/readme.txt
[Mon Feb 01 21:48:49.210183 2021] [wsgi:error] [pid 24147:tid 140505224800000] [remote 45.155.205.108:58500] Not Found: /Autodiscover/Autodiscover.xml
[Mon Feb 01 21:48:49.575963 2021] [wsgi:error] [pid 24148:tid 140505384261376] [remote 45.155.205.108:34676] Not Found: /console/
[Mon Feb 01 21:48:52.207673 2021] [wsgi:error] [pid 24147:tid 140505384261376] [remote 45.155.205.108:53340] Not Found: /_ignition/execute-solution
[Mon Feb 01 22:48:42.979520 2021] [wsgi:error] [pid 24148:tid 140505182836480] [remote 192.241.195.6:43112] Not Found: /actuator/health
[Tue Feb 02 00:23:09.494120 2021] [wsgi:error] [pid 24148:tid 140505384261376] [remote 51.132.6.77:51900] Not Found: /.env
[Tue Feb 02 00:23:09.998522 2021] [wsgi:error] [pid 24147:tid 140505384261376] [remote 51.132.6.77:51917] Forbidden (Referer checking failed - no Referer.): /
Exception ignored in: <bound method BaseEventLoop.__del__ of <_UnixSelectorEventLoop running=False closed=False debug=False>>
Traceback (most recent call last):
  File "/usr/lib/python3.6/asyncio/base_events.py", line 526, in __del__
NameError: name 'ResourceWarning' is not defined
Exception ignored in: <bound method BaseEventLoop.__del__ of <_UnixSelectorEventLoop running=False closed=False debug=False>>
Traceback (most recent call last):
  File "/usr/lib/python3.6/asyncio/base_events.py", line 526, in __del__
NameError: name 'ResourceWarning' is not defined
[Tue Feb 02 07:27:50.443437 2021] [wsgi:error] [pid 32416:tid 140505283548928] [remote 34.212.251.176:55660] mod_wsgi (pid=32416): Target WSGI script '/var/www/HonestyNetwork/HonestyNetwork/wsgi.py' cannot be loaded as Python module.
[Tue Feb 02 07:27:50.443530 2021] [wsgi:error] [pid 32416:tid 140505283548928] [remote 34.212.251.176:55660] mod_wsgi (pid=32416): Exception occurred processing WSGI script '/var/www/HonestyNetwork/HonestyNetwork/wsgi.py'.
[Tue Feb 02 07:27:50.444611 2021] [wsgi:error] [pid 32416:tid 140505283548928] [remote 34.212.251.176:55660] Traceback (most recent call last):
[Tue Feb 02 07:27:50.444678 2021] [wsgi:error] [pid 32416:tid 140505283548928] [remote 34.212.251.176:55660]   File "/var/www/HonestyNetwork/HonestyNetwork/wsgi.py", line 16, in <module>
[Tue Feb 02 07:27:50.444684 2021] [wsgi:error] [pid 32416:tid 140505283548928] [remote 34.212.251.176:55660]     application = get_wsgi_application()
[Tue Feb 02 07:27:50.444692 2021] [wsgi:error] [pid 32416:tid 140505283548928] [remote 34.212.251.176:55660]   File "/usr/local/lib/python3.6/dist-packages/django/core/wsgi.py", line 12, in get_wsgi_application
[Tue Feb 02 07:27:50.444696 2021] [wsgi:error] [pid 32416:tid 140505283548928] [remote 34.212.251.176:55660]     django.setup(set_prefix=False)
[Tue Feb 02 07:27:50.444703 2021] [wsgi:error] [pid 32416:tid 140505283548928] [remote 34.212.251.176:55660]   File "/usr/local/lib/python3.6/dist-packages/django/__init__.py", line 24, in setup
[Tue Feb 02 07:27:50.444706 2021] [wsgi:error] [pid 32416:tid 140505283548928] [remote 34.212.251.176:55660]     apps.populate(settings.INSTALLED_APPS)
[Tue Feb 02 07:27:50.444713 2021] [wsgi:error] [pid 32416:tid 140505283548928] [remote 34.212.251.176:55660]   File "/usr/local/lib/python3.6/dist-packages/django/apps/registry.py", line 91, in populate
[Tue Feb 02 07:27:50.444717 2021] [wsgi:error] [pid 32416:tid 140505283548928] [remote 34.212.251.176:55660]     app_config = AppConfig.create(entry)
[Tue Feb 02 07:27:50.444723 2021] [wsgi:error] [pid 32416:tid 140505283548928] [remote 34.212.251.176:55660]   File "/usr/local/lib/python3.6/dist-packages/django/apps/config.py", line 90, in create
[Tue Feb 02 07:27:50.444727 2021] [wsgi:error] [pid 32416:tid 140505283548928] [remote 34.212.251.176:55660]     module = import_module(entry)
[Tue Feb 02 07:27:50.444733 2021] [wsgi:error] [pid 32416:tid 140505283548928] [remote 34.212.251.176:55660]   File "/usr/lib/python3.6/importlib/__init__.py", line 126, in import_module
[Tue Feb 02 07:27:50.444756 2021] [wsgi:error] [pid 32416:tid 140505283548928] [remote 34.212.251.176:55660]     return _bootstrap._gcd_import(name[level:], package, level)
[Tue Feb 02 07:27:50.444764 2021] [wsgi:error] [pid 32416:tid 140505283548928] [remote 34.212.251.176:55660]   File "<frozen importlib._bootstrap>", line 994, in _gcd_import
[Tue Feb 02 07:27:50.444771 2021] [wsgi:error] [pid 32416:tid 140505283548928] [remote 34.212.251.176:55660]   File "<frozen importlib._bootstrap>", line 971, in _find_and_load
[Tue Feb 02 07:27:50.444777 2021] [wsgi:error] [pid 32416:tid 140505283548928] [remote 34.212.251.176:55660]   File "<frozen importlib._bootstrap>", line 953, in _find_and_load_unlocked
[Tue Feb 02 07:27:50.444801 2021] [wsgi:error] [pid 32416:tid 140505283548928] [remote 34.212.251.176:55660] ModuleNotFoundError: No module named 'sslserver'
[Tue Feb 02 07:36:09.026797 2021] [wsgi:error] [pid 32415:tid 140505350690560] [remote 71.6.232.7:47732] mod_wsgi (pid=32415): Target WSGI script '/var/www/HonestyNetwork/HonestyNetwork/wsgi.py' cannot be loaded as Python module.
[Tue Feb 02 07:36:09.026914 2021] [wsgi:error] [pid 32415:tid 140505350690560] [remote 71.6.232.7:47732] mod_wsgi (pid=32415): Exception occurred processing WSGI script '/var/www/HonestyNetwork/HonestyNetwork/wsgi.py'.
[Tue Feb 02 07:36:09.028025 2021] [wsgi:error] [pid 32415:tid 140505350690560] [remote 71.6.232.7:47732] Traceback (most recent call last):
[Tue Feb 02 07:36:09.028090 2021] [wsgi:error] [pid 32415:tid 140505350690560] [remote 71.6.232.7:47732]   File "/var/www/HonestyNetwork/HonestyNetwork/wsgi.py", line 16, in <module>
[Tue Feb 02 07:36:09.028097 2021] [wsgi:error] [pid 32415:tid 140505350690560] [remote 71.6.232.7:47732]     application = get_wsgi_application()
[Tue Feb 02 07:36:09.028105 2021] [wsgi:error] [pid 32415:tid 140505350690560] [remote 71.6.232.7:47732]   File "/usr/local/lib/python3.6/dist-packages/django/core/wsgi.py", line 12, in get_wsgi_application
[Tue Feb 02 07:36:09.028109 2021] [wsgi:error] [pid 32415:tid 140505350690560] [remote 71.6.232.7:47732]     django.setup(set_prefix=False)
[Tue Feb 02 07:36:09.028117 2021] [wsgi:error] [pid 32415:tid 140505350690560] [remote 71.6.232.7:47732]   File "/usr/local/lib/python3.6/dist-packages/django/__init__.py", line 24, in setup
[Tue Feb 02 07:36:09.028121 2021] [wsgi:error] [pid 32415:tid 140505350690560] [remote 71.6.232.7:47732]     apps.populate(settings.INSTALLED_APPS)
[Tue Feb 02 07:36:09.028128 2021] [wsgi:error] [pid 32415:tid 140505350690560] [remote 71.6.232.7:47732]   File "/usr/local/lib/python3.6/dist-packages/django/apps/registry.py", line 91, in populate
[Tue Feb 02 07:36:09.028131 2021] [wsgi:error] [pid 32415:tid 140505350690560] [remote 71.6.232.7:47732]     app_config = AppConfig.create(entry)
[Tue Feb 02 07:36:09.028138 2021] [wsgi:error] [pid 32415:tid 140505350690560] [remote 71.6.232.7:47732]   File "/usr/local/lib/python3.6/dist-packages/django/apps/config.py", line 90, in create
[Tue Feb 02 07:36:09.028141 2021] [wsgi:error] [pid 32415:tid 140505350690560] [remote 71.6.232.7:47732]     module = import_module(entry)
[Tue Feb 02 07:36:09.028148 2021] [wsgi:error] [pid 32415:tid 140505350690560] [remote 71.6.232.7:47732]   File "/usr/lib/python3.6/importlib/__init__.py", line 126, in import_module
[Tue Feb 02 07:36:09.028152 2021] [wsgi:error] [pid 32415:tid 140505350690560] [remote 71.6.232.7:47732]     return _bootstrap._gcd_import(name[level:], package, level)
[Tue Feb 02 07:36:09.028158 2021] [wsgi:error] [pid 32415:tid 140505350690560] [remote 71.6.232.7:47732]   File "<frozen importlib._bootstrap>", line 994, in _gcd_import
[Tue Feb 02 07:36:09.028165 2021] [wsgi:error] [pid 32415:tid 140505350690560] [remote 71.6.232.7:47732]   File "<frozen importlib._bootstrap>", line 971, in _find_and_load
[Tue Feb 02 07:36:09.028173 2021] [wsgi:error] [pid 32415:tid 140505350690560] [remote 71.6.232.7:47732]   File "<frozen importlib._bootstrap>", line 953, in _find_and_load_unlocked
[Tue Feb 02 07:36:09.028220 2021] [wsgi:error] [pid 32415:tid 140505350690560] [remote 71.6.232.7:47732] ModuleNotFoundError: No module named 'sslserver'
[Tue Feb 02 08:57:27.792153 2021] [wsgi:error] [pid 32416:tid 140505182836480] [remote 195.154.61.206:59301] mod_wsgi (pid=32416): Target WSGI script '/var/www/HonestyNetwork/HonestyNetwork/wsgi.py' cannot be loaded as Python module.
[Tue Feb 02 08:57:27.792380 2021] [wsgi:error] [pid 32416:tid 140505182836480] [remote 195.154.61.206:59301] mod_wsgi (pid=32416): Exception occurred processing WSGI script '/var/www/HonestyNetwork/HonestyNetwork/wsgi.py'.
[Tue Feb 02 08:57:27.792944 2021] [wsgi:error] [pid 32416:tid 140505182836480] [remote 195.154.61.206:59301] Traceback (most recent call last):
[Tue Feb 02 08:57:27.793046 2021] [wsgi:error] [pid 32416:tid 140505182836480] [remote 195.154.61.206:59301]   File "/var/www/HonestyNetwork/HonestyNetwork/wsgi.py", line 16, in <module>
[Tue Feb 02 08:57:27.793055 2021] [wsgi:error] [pid 32416:tid 140505182836480] [remote 195.154.61.206:59301]     application = get_wsgi_application()
[Tue Feb 02 08:57:27.793079 2021] [wsgi:error] [pid 32416:tid 140505182836480] [remote 195.154.61.206:59301]   File "/usr/local/lib/python3.6/dist-packages/django/core/wsgi.py", line 12, in get_wsgi_application
[Tue Feb 02 08:57:27.793084 2021] [wsgi:error] [pid 32416:tid 140505182836480] [remote 195.154.61.206:59301]     django.setup(set_prefix=False)
[Tue Feb 02 08:57:27.793095 2021] [wsgi:error] [pid 32416:tid 140505182836480] [remote 195.154.61.206:59301]   File "/usr/local/lib/python3.6/dist-packages/django/__init__.py", line 24, in setup
[Tue Feb 02 08:57:27.793100 2021] [wsgi:error] [pid 32416:tid 140505182836480] [remote 195.154.61.206:59301]     apps.populate(settings.INSTALLED_APPS)
[Tue Feb 02 08:57:27.793109 2021] [wsgi:error] [pid 32416:tid 140505182836480] [remote 195.154.61.206:59301]   File "/usr/local/lib/python3.6/dist-packages/django/apps/registry.py", line 83, in populate
[Tue Feb 02 08:57:27.793113 2021] [wsgi:error] [pid 32416:tid 140505182836480] [remote 195.154.61.206:59301]     raise RuntimeError("populate() isn't reentrant")
[Tue Feb 02 08:57:27.793149 2021] [wsgi:error] [pid 32416:tid 140505182836480] [remote 195.154.61.206:59301] RuntimeError: populate() isn't reentrant
[Tue Feb 02 09:13:08.590806 2021] [wsgi:error] [pid 32415:tid 140505384261376] [remote 179.62.132.17:6032] mod_wsgi (pid=32415): Target WSGI script '/var/www/HonestyNetwork/HonestyNetwork/wsgi.py' cannot be loaded as Python module.
[Tue Feb 02 09:13:08.591122 2021] [wsgi:error] [pid 32415:tid 140505384261376] [remote 179.62.132.17:6032] mod_wsgi (pid=32415): Exception occurred processing WSGI script '/var/www/HonestyNetwork/HonestyNetwork/wsgi.py'.
[Tue Feb 02 09:13:08.591816 2021] [wsgi:error] [pid 32415:tid 140505384261376] [remote 179.62.132.17:6032] Traceback (most recent call last):
[Tue Feb 02 09:13:08.591910 2021] [wsgi:error] [pid 32415:tid 140505384261376] [remote 179.62.132.17:6032]   File "/var/www/HonestyNetwork/HonestyNetwork/wsgi.py", line 16, in <module>
[Tue Feb 02 09:13:08.591917 2021] [wsgi:error] [pid 32415:tid 140505384261376] [remote 179.62.132.17:6032]     application = get_wsgi_application()
[Tue Feb 02 09:13:08.591939 2021] [wsgi:error] [pid 32415:tid 140505384261376] [remote 179.62.132.17:6032]   File "/usr/local/lib/python3.6/dist-packages/django/core/wsgi.py", line 12, in get_wsgi_application
[Tue Feb 02 09:13:08.591943 2021] [wsgi:error] [pid 32415:tid 140505384261376] [remote 179.62.132.17:6032]     django.setup(set_prefix=False)
[Tue Feb 02 09:13:08.591951 2021] [wsgi:error] [pid 32415:tid 140505384261376] [remote 179.62.132.17:6032]   File "/usr/local/lib/python3.6/dist-packages/django/__init__.py", line 24, in setup
[Tue Feb 02 09:13:08.591955 2021] [wsgi:error] [pid 32415:tid 140505384261376] [remote 179.62.132.17:6032]     apps.populate(settings.INSTALLED_APPS)
[Tue Feb 02 09:13:08.591962 2021] [wsgi:error] [pid 32415:tid 140505384261376] [remote 179.62.132.17:6032]   File "/usr/local/lib/python3.6/dist-packages/django/apps/registry.py", line 83, in populate
[Tue Feb 02 09:13:08.591981 2021] [wsgi:error] [pid 32415:tid 140505384261376] [remote 179.62.132.17:6032]     raise RuntimeError("populate() isn't reentrant")
[Tue Feb 02 09:13:08.592030 2021] [wsgi:error] [pid 32415:tid 140505384261376] [remote 179.62.132.17:6032] RuntimeError: populate() isn't reentrant
[Tue Feb 02 09:13:43.746623 2021] [wsgi:error] [pid 32416:tid 140505283548928] [remote 128.14.134.170:48848] mod_wsgi (pid=32416): Target WSGI script '/var/www/HonestyNetwork/HonestyNetwork/wsgi.py' cannot be loaded as Python module.
[Tue Feb 02 09:13:43.746895 2021] [wsgi:error] [pid 32416:tid 140505283548928] [remote 128.14.134.170:48848] mod_wsgi (pid=32416): Exception occurred processing WSGI script '/var/www/HonestyNetwork/HonestyNetwork/wsgi.py'.
[Tue Feb 02 09:13:43.747554 2021] [wsgi:error] [pid 32416:tid 140505283548928] [remote 128.14.134.170:48848] Traceback (most recent call last):
[Tue Feb 02 09:13:43.747644 2021] [wsgi:error] [pid 32416:tid 140505283548928] [remote 128.14.134.170:48848]   File "/var/www/HonestyNetwork/HonestyNetwork/wsgi.py", line 16, in <module>
[Tue Feb 02 09:13:43.747660 2021] [wsgi:error] [pid 32416:tid 140505283548928] [remote 128.14.134.170:48848]     application = get_wsgi_application()
[Tue Feb 02 09:13:43.747691 2021] [wsgi:error] [pid 32416:tid 140505283548928] [remote 128.14.134.170:48848]   File "/usr/local/lib/python3.6/dist-packages/django/core/wsgi.py", line 12, in get_wsgi_application
[Tue Feb 02 09:13:43.747697 2021] [wsgi:error] [pid 32416:tid 140505283548928] [remote 128.14.134.170:48848]     django.setup(set_prefix=False)
[Tue Feb 02 09:13:43.747708 2021] [wsgi:error] [pid 32416:tid 140505283548928] [remote 128.14.134.170:48848]   File "/usr/local/lib/python3.6/dist-packages/django/__init__.py", line 24, in setup
[Tue Feb 02 09:13:43.747714 2021] [wsgi:error] [pid 32416:tid 140505283548928] [remote 128.14.134.170:48848]     apps.populate(settings.INSTALLED_APPS)
[Tue Feb 02 09:13:43.747724 2021] [wsgi:error] [pid 32416:tid 140505283548928] [remote 128.14.134.170:48848]   File "/usr/local/lib/python3.6/dist-packages/django/apps/registry.py", line 83, in populate
[Tue Feb 02 09:13:43.747729 2021] [wsgi:error] [pid 32416:tid 140505283548928] [remote 128.14.134.170:48848]     raise RuntimeError("populate() isn't reentrant")
[Tue Feb 02 09:13:43.747768 2021] [wsgi:error] [pid 32416:tid 140505283548928] [remote 128.14.134.170:48848] RuntimeError: populate() isn't reentrant
[Tue Feb 02 09:33:39.720870 2021] [wsgi:error] [pid 32415:tid 140505350690560] [remote 62.210.10.77:39067] mod_wsgi (pid=32415): Target WSGI script '/var/www/HonestyNetwork/HonestyNetwork/wsgi.py' cannot be loaded as Python module.
[Tue Feb 02 09:33:39.721058 2021] [wsgi:error] [pid 32415:tid 140505350690560] [remote 62.210.10.77:39067] mod_wsgi (pid=32415): Exception occurred processing WSGI script '/var/www/HonestyNetwork/HonestyNetwork/wsgi.py'.
[Tue Feb 02 09:33:39.721577 2021] [wsgi:error] [pid 32415:tid 140505350690560] [remote 62.210.10.77:39067] Traceback (most recent call last):
[Tue Feb 02 09:33:39.721650 2021] [wsgi:error] [pid 32415:tid 140505350690560] [remote 62.210.10.77:39067]   File "/var/www/HonestyNetwork/HonestyNetwork/wsgi.py", line 16, in <module>
[Tue Feb 02 09:33:39.721660 2021] [wsgi:error] [pid 32415:tid 140505350690560] [remote 62.210.10.77:39067]     application = get_wsgi_application()
[Tue Feb 02 09:33:39.721674 2021] [wsgi:error] [pid 32415:tid 140505350690560] [remote 62.210.10.77:39067]   File "/usr/local/lib/python3.6/dist-packages/django/core/wsgi.py", line 12, in get_wsgi_application
[Tue Feb 02 09:33:39.721679 2021] [wsgi:error] [pid 32415:tid 140505350690560] [remote 62.210.10.77:39067]     django.setup(set_prefix=False)
[Tue Feb 02 09:33:39.721686 2021] [wsgi:error] [pid 32415:tid 140505350690560] [remote 62.210.10.77:39067]   File "/usr/local/lib/python3.6/dist-packages/django/__init__.py", line 24, in setup
[Tue Feb 02 09:33:39.721690 2021] [wsgi:error] [pid 32415:tid 140505350690560] [remote 62.210.10.77:39067]     apps.populate(settings.INSTALLED_APPS)
[Tue Feb 02 09:33:39.721713 2021] [wsgi:error] [pid 32415:tid 140505350690560] [remote 62.210.10.77:39067]   File "/usr/local/lib/python3.6/dist-packages/django/apps/registry.py", line 83, in populate
[Tue Feb 02 09:33:39.721719 2021] [wsgi:error] [pid 32415:tid 140505350690560] [remote 62.210.10.77:39067]     raise RuntimeError("populate() isn't reentrant")
[Tue Feb 02 09:33:39.721762 2021] [wsgi:error] [pid 32415:tid 140505350690560] [remote 62.210.10.77:39067] RuntimeError: populate() isn't reentrant
[Tue Feb 02 09:40:54.036933 2021] [wsgi:error] [pid 32416:tid 140505182836480] [remote 83.97.20.29:62083] mod_wsgi (pid=32416): Target WSGI script '/var/www/HonestyNetwork/HonestyNetwork/wsgi.py' cannot be loaded as Python module.
[Tue Feb 02 09:40:54.037163 2021] [wsgi:error] [pid 32416:tid 140505182836480] [remote 83.97.20.29:62083] mod_wsgi (pid=32416): Exception occurred processing WSGI script '/var/www/HonestyNetwork/HonestyNetwork/wsgi.py'.
[Tue Feb 02 09:40:54.037881 2021] [wsgi:error] [pid 32416:tid 140505182836480] [remote 83.97.20.29:62083] Traceback (most recent call last):
[Tue Feb 02 09:40:54.037987 2021] [wsgi:error] [pid 32416:tid 140505182836480] [remote 83.97.20.29:62083]   File "/var/www/HonestyNetwork/HonestyNetwork/wsgi.py", line 16, in <module>
[Tue Feb 02 09:40:54.037997 2021] [wsgi:error] [pid 32416:tid 140505182836480] [remote 83.97.20.29:62083]     application = get_wsgi_application()
[Tue Feb 02 09:40:54.038020 2021] [wsgi:error] [pid 32416:tid 140505182836480] [remote 83.97.20.29:62083]   File "/usr/local/lib/python3.6/dist-packages/django/core/wsgi.py", line 12, in get_wsgi_application
[Tue Feb 02 09:40:54.038027 2021] [wsgi:error] [pid 32416:tid 140505182836480] [remote 83.97.20.29:62083]     django.setup(set_prefix=False)
[Tue Feb 02 09:40:54.038037 2021] [wsgi:error] [pid 32416:tid 140505182836480] [remote 83.97.20.29:62083]   File "/usr/local/lib/python3.6/dist-packages/django/__init__.py", line 24, in setup
[Tue Feb 02 09:40:54.038042 2021] [wsgi:error] [pid 32416:tid 140505182836480] [remote 83.97.20.29:62083]     apps.populate(settings.INSTALLED_APPS)
[Tue Feb 02 09:40:54.038051 2021] [wsgi:error] [pid 32416:tid 140505182836480] [remote 83.97.20.29:62083]   File "/usr/local/lib/python3.6/dist-packages/django/apps/registry.py", line 83, in populate
[Tue Feb 02 09:40:54.038056 2021] [wsgi:error] [pid 32416:tid 140505182836480] [remote 83.97.20.29:62083]     raise RuntimeError("populate() isn't reentrant")
[Tue Feb 02 09:40:54.038091 2021] [wsgi:error] [pid 32416:tid 140505182836480] [remote 83.97.20.29:62083] RuntimeError: populate() isn't reentrant
[Tue Feb 02 09:47:16.308716 2021] [wsgi:error] [pid 32415:tid 140505384261376] [remote 66.249.64.64:54407] mod_wsgi (pid=32415): Target WSGI script '/var/www/HonestyNetwork/HonestyNetwork/wsgi.py' cannot be loaded as Python module.
[Tue Feb 02 09:47:16.309037 2021] [wsgi:error] [pid 32415:tid 140505384261376] [remote 66.249.64.64:54407] mod_wsgi (pid=32415): Exception occurred processing WSGI script '/var/www/HonestyNetwork/HonestyNetwork/wsgi.py'.
[Tue Feb 02 09:47:16.309839 2021] [wsgi:error] [pid 32415:tid 140505384261376] [remote 66.249.64.64:54407] Traceback (most recent call last):
[Tue Feb 02 09:47:16.309951 2021] [wsgi:error] [pid 32415:tid 140505384261376] [remote 66.249.64.64:54407]   File "/var/www/HonestyNetwork/HonestyNetwork/wsgi.py", line 16, in <module>
[Tue Feb 02 09:47:16.309958 2021] [wsgi:error] [pid 32415:tid 140505384261376] [remote 66.249.64.64:54407]     application = get_wsgi_application()
[Tue Feb 02 09:47:16.309978 2021] [wsgi:error] [pid 32415:tid 140505384261376] [remote 66.249.64.64:54407]   File "/usr/local/lib/python3.6/dist-packages/django/core/wsgi.py", line 12, in get_wsgi_application
[Tue Feb 02 09:47:16.309983 2021] [wsgi:error] [pid 32415:tid 140505384261376] [remote 66.249.64.64:54407]     django.setup(set_prefix=False)
[Tue Feb 02 09:47:16.309990 2021] [wsgi:error] [pid 32415:tid 140505384261376] [remote 66.249.64.64:54407]   File "/usr/local/lib/python3.6/dist-packages/django/__init__.py", line 24, in setup
[Tue Feb 02 09:47:16.310013 2021] [wsgi:error] [pid 32415:tid 140505384261376] [remote 66.249.64.64:54407]     apps.populate(settings.INSTALLED_APPS)
[Tue Feb 02 09:47:16.310020 2021] [wsgi:error] [pid 32415:tid 140505384261376] [remote 66.249.64.64:54407]   File "/usr/local/lib/python3.6/dist-packages/django/apps/registry.py", line 83, in populate
[Tue Feb 02 09:47:16.310023 2021] [wsgi:error] [pid 32415:tid 140505384261376] [remote 66.249.64.64:54407]     raise RuntimeError("populate() isn't reentrant")
[Tue Feb 02 09:47:16.310077 2021] [wsgi:error] [pid 32415:tid 140505384261376] [remote 66.249.64.64:54407] RuntimeError: populate() isn't reentrant
[Tue Feb 02 11:28:29.376528 2021] [wsgi:error] [pid 32416:tid 140505283548928] [remote 213.32.76.91:34888] mod_wsgi (pid=32416): Target WSGI script '/var/www/HonestyNetwork/HonestyNetwork/wsgi.py' cannot be loaded as Python module.
[Tue Feb 02 11:28:29.376810 2021] [wsgi:error] [pid 32416:tid 140505283548928] [remote 213.32.76.91:34888] mod_wsgi (pid=32416): Exception occurred processing WSGI script '/var/www/HonestyNetwork/HonestyNetwork/wsgi.py'.
[Tue Feb 02 11:28:29.377604 2021] [wsgi:error] [pid 32416:tid 140505283548928] [remote 213.32.76.91:34888] Traceback (most recent call last):
[Tue Feb 02 11:28:29.377723 2021] [wsgi:error] [pid 32416:tid 140505283548928] [remote 213.32.76.91:34888]   File "/var/www/HonestyNetwork/HonestyNetwork/wsgi.py", line 16, in <module>
[Tue Feb 02 11:28:29.377740 2021] [wsgi:error] [pid 32416:tid 140505283548928] [remote 213.32.76.91:34888]     application = get_wsgi_application()
[Tue Feb 02 11:28:29.377773 2021] [wsgi:error] [pid 32416:tid 140505283548928] [remote 213.32.76.91:34888]   File "/usr/local/lib/python3.6/dist-packages/django/core/wsgi.py", line 12, in get_wsgi_application
[Tue Feb 02 11:28:29.377779 2021] [wsgi:error] [pid 32416:tid 140505283548928] [remote 213.32.76.91:34888]     django.setup(set_prefix=False)
[Tue Feb 02 11:28:29.377790 2021] [wsgi:error] [pid 32416:tid 140505283548928] [remote 213.32.76.91:34888]   File "/usr/local/lib/python3.6/dist-packages/django/__init__.py", line 24, in setup
[Tue Feb 02 11:28:29.377796 2021] [wsgi:error] [pid 32416:tid 140505283548928] [remote 213.32.76.91:34888]     apps.populate(settings.INSTALLED_APPS)
[Tue Feb 02 11:28:29.377805 2021] [wsgi:error] [pid 32416:tid 140505283548928] [remote 213.32.76.91:34888]   File "/usr/local/lib/python3.6/dist-packages/django/apps/registry.py", line 83, in populate
[Tue Feb 02 11:28:29.377810 2021] [wsgi:error] [pid 32416:tid 140505283548928] [remote 213.32.76.91:34888]     raise RuntimeError("populate() isn't reentrant")
[Tue Feb 02 11:28:29.377849 2021] [wsgi:error] [pid 32416:tid 140505283548928] [remote 213.32.76.91:34888] RuntimeError: populate() isn't reentrant
[Tue Feb 02 11:38:56.233132 2021] [wsgi:error] [pid 32415:tid 140505350690560] [remote 173.236.9.250:48762] mod_wsgi (pid=32415): Target WSGI script '/var/www/HonestyNetwork/HonestyNetwork/wsgi.py' cannot be loaded as Python module.
[Tue Feb 02 11:38:56.233567 2021] [wsgi:error] [pid 32415:tid 140505350690560] [remote 173.236.9.250:48762] mod_wsgi (pid=32415): Exception occurred processing WSGI script '/var/www/HonestyNetwork/HonestyNetwork/wsgi.py'.
[Tue Feb 02 11:38:56.234258 2021] [wsgi:error] [pid 32415:tid 140505350690560] [remote 173.236.9.250:48762] Traceback (most recent call last):
[Tue Feb 02 11:38:56.234363 2021] [wsgi:error] [pid 32415:tid 140505350690560] [remote 173.236.9.250:48762]   File "/var/www/HonestyNetwork/HonestyNetwork/wsgi.py", line 16, in <module>
[Tue Feb 02 11:38:56.234378 2021] [wsgi:error] [pid 32415:tid 140505350690560] [remote 173.236.9.250:48762]     application = get_wsgi_application()
[Tue Feb 02 11:38:56.234396 2021] [wsgi:error] [pid 32415:tid 140505350690560] [remote 173.236.9.250:48762]   File "/usr/local/lib/python3.6/dist-packages/django/core/wsgi.py", line 12, in get_wsgi_application
[Tue Feb 02 11:38:56.234403 2021] [wsgi:error] [pid 32415:tid 140505350690560] [remote 173.236.9.250:48762]     django.setup(set_prefix=False)
[Tue Feb 02 11:38:56.234430 2021] [wsgi:error] [pid 32415:tid 140505350690560] [remote 173.236.9.250:48762]   File "/usr/local/lib/python3.6/dist-packages/django/__init__.py", line 24, in setup
[Tue Feb 02 11:38:56.234436 2021] [wsgi:error] [pid 32415:tid 140505350690560] [remote 173.236.9.250:48762]     apps.populate(settings.INSTALLED_APPS)
[Tue Feb 02 11:38:56.234444 2021] [wsgi:error] [pid 32415:tid 140505350690560] [remote 173.236.9.250:48762]   File "/usr/local/lib/python3.6/dist-packages/django/apps/registry.py", line 83, in populate
[Tue Feb 02 11:38:56.234448 2021] [wsgi:error] [pid 32415:tid 140505350690560] [remote 173.236.9.250:48762]     raise RuntimeError("populate() isn't reentrant")
[Tue Feb 02 11:38:56.234499 2021] [wsgi:error] [pid 32415:tid 140505350690560] [remote 173.236.9.250:48762] RuntimeError: populate() isn't reentrant
[Tue Feb 02 11:52:38.495696 2021] [wsgi:error] [pid 32416:tid 140505182836480] [remote 192.241.220.203:49466] mod_wsgi (pid=32416): Target WSGI script '/var/www/HonestyNetwork/HonestyNetwork/wsgi.py' cannot be loaded as Python module.
[Tue Feb 02 11:52:38.495944 2021] [wsgi:error] [pid 32416:tid 140505182836480] [remote 192.241.220.203:49466] mod_wsgi (pid=32416): Exception occurred processing WSGI script '/var/www/HonestyNetwork/HonestyNetwork/wsgi.py'.
[Tue Feb 02 11:52:38.496447 2021] [wsgi:error] [pid 32416:tid 140505182836480] [remote 192.241.220.203:49466] Traceback (most recent call last):
[Tue Feb 02 11:52:38.496581 2021] [wsgi:error] [pid 32416:tid 140505182836480] [remote 192.241.220.203:49466]   File "/var/www/HonestyNetwork/HonestyNetwork/wsgi.py", line 16, in <module>
[Tue Feb 02 11:52:38.496589 2021] [wsgi:error] [pid 32416:tid 140505182836480] [remote 192.241.220.203:49466]     application = get_wsgi_application()
[Tue Feb 02 11:52:38.496608 2021] [wsgi:error] [pid 32416:tid 140505182836480] [remote 192.241.220.203:49466]   File "/usr/local/lib/python3.6/dist-packages/django/core/wsgi.py", line 12, in get_wsgi_application
[Tue Feb 02 11:52:38.496612 2021] [wsgi:error] [pid 32416:tid 140505182836480] [remote 192.241.220.203:49466]     django.setup(set_prefix=False)
[Tue Feb 02 11:52:38.496620 2021] [wsgi:error] [pid 32416:tid 140505182836480] [remote 192.241.220.203:49466]   File "/usr/local/lib/python3.6/dist-packages/django/__init__.py", line 24, in setup
[Tue Feb 02 11:52:38.496623 2021] [wsgi:error] [pid 32416:tid 140505182836480] [remote 192.241.220.203:49466]     apps.populate(settings.INSTALLED_APPS)
[Tue Feb 02 11:52:38.496631 2021] [wsgi:error] [pid 32416:tid 140505182836480] [remote 192.241.220.203:49466]   File "/usr/local/lib/python3.6/dist-packages/django/apps/registry.py", line 83, in populate
[Tue Feb 02 11:52:38.496634 2021] [wsgi:error] [pid 32416:tid 140505182836480] [remote 192.241.220.203:49466]     raise RuntimeError("populate() isn't reentrant")
[Tue Feb 02 11:52:38.496668 2021] [wsgi:error] [pid 32416:tid 140505182836480] [remote 192.241.220.203:49466] RuntimeError: populate() isn't reentrant
[Tue Feb 02 12:08:42.242428 2021] [wsgi:error] [pid 32415:tid 140505384261376] [remote 66.249.64.66:42994] mod_wsgi (pid=32415): Target WSGI script '/var/www/HonestyNetwork/HonestyNetwork/wsgi.py' cannot be loaded as Python module.
[Tue Feb 02 12:08:42.242696 2021] [wsgi:error] [pid 32415:tid 140505384261376] [remote 66.249.64.66:42994] mod_wsgi (pid=32415): Exception occurred processing WSGI script '/var/www/HonestyNetwork/HonestyNetwork/wsgi.py'.
[Tue Feb 02 12:08:42.243241 2021] [wsgi:error] [pid 32415:tid 140505384261376] [remote 66.249.64.66:42994] Traceback (most recent call last):
[Tue Feb 02 12:08:42.243344 2021] [wsgi:error] [pid 32415:tid 140505384261376] [remote 66.249.64.66:42994]   File "/var/www/HonestyNetwork/HonestyNetwork/wsgi.py", line 16, in <module>
[Tue Feb 02 12:08:42.243354 2021] [wsgi:error] [pid 32415:tid 140505384261376] [remote 66.249.64.66:42994]     application = get_wsgi_application()
[Tue Feb 02 12:08:42.243373 2021] [wsgi:error] [pid 32415:tid 140505384261376] [remote 66.249.64.66:42994]   File "/usr/local/lib/python3.6/dist-packages/django/core/wsgi.py", line 12, in get_wsgi_application
[Tue Feb 02 12:08:42.243399 2021] [wsgi:error] [pid 32415:tid 140505384261376] [remote 66.249.64.66:42994]     django.setup(set_prefix=False)
[Tue Feb 02 12:08:42.243411 2021] [wsgi:error] [pid 32415:tid 140505384261376] [remote 66.249.64.66:42994]   File "/usr/local/lib/python3.6/dist-packages/django/__init__.py", line 24, in setup
[Tue Feb 02 12:08:42.243415 2021] [wsgi:error] [pid 32415:tid 140505384261376] [remote 66.249.64.66:42994]     apps.populate(settings.INSTALLED_APPS)
[Tue Feb 02 12:08:42.243425 2021] [wsgi:error] [pid 32415:tid 140505384261376] [remote 66.249.64.66:42994]   File "/usr/local/lib/python3.6/dist-packages/django/apps/registry.py", line 83, in populate
[Tue Feb 02 12:08:42.243429 2021] [wsgi:error] [pid 32415:tid 140505384261376] [remote 66.249.64.66:42994]     raise RuntimeError("populate() isn't reentrant")
[Tue Feb 02 12:08:42.243475 2021] [wsgi:error] [pid 32415:tid 140505384261376] [remote 66.249.64.66:42994] RuntimeError: populate() isn't reentrant
[Tue Feb 02 12:43:00.344736 2021] [wsgi:error] [pid 32416:tid 140505283548928] [remote 167.248.133.54:38748] mod_wsgi (pid=32416): Target WSGI script '/var/www/HonestyNetwork/HonestyNetwork/wsgi.py' cannot be loaded as Python module.
[Tue Feb 02 12:43:00.345168 2021] [wsgi:error] [pid 32416:tid 140505283548928] [remote 167.248.133.54:38748] mod_wsgi (pid=32416): Exception occurred processing WSGI script '/var/www/HonestyNetwork/HonestyNetwork/wsgi.py'.
[Tue Feb 02 12:43:00.346173 2021] [wsgi:error] [pid 32416:tid 140505283548928] [remote 167.248.133.54:38748] Traceback (most recent call last):
[Tue Feb 02 12:43:00.346354 2021] [wsgi:error] [pid 32416:tid 140505283548928] [remote 167.248.133.54:38748]   File "/var/www/HonestyNetwork/HonestyNetwork/wsgi.py", line 16, in <module>
[Tue Feb 02 12:43:00.346375 2021] [wsgi:error] [pid 32416:tid 140505283548928] [remote 167.248.133.54:38748]     application = get_wsgi_application()
[Tue Feb 02 12:43:00.346409 2021] [wsgi:error] [pid 32416:tid 140505283548928] [remote 167.248.133.54:38748]   File "/usr/local/lib/python3.6/dist-packages/django/core/wsgi.py", line 12, in get_wsgi_application
[Tue Feb 02 12:43:00.346415 2021] [wsgi:error] [pid 32416:tid 140505283548928] [remote 167.248.133.54:38748]     django.setup(set_prefix=False)
[Tue Feb 02 12:43:00.346426 2021] [wsgi:error] [pid 32416:tid 140505283548928] [remote 167.248.133.54:38748]   File "/usr/local/lib/python3.6/dist-packages/django/__init__.py", line 24, in setup
[Tue Feb 02 12:43:00.346430 2021] [wsgi:error] [pid 32416:tid 140505283548928] [remote 167.248.133.54:38748]     apps.populate(settings.INSTALLED_APPS)
[Tue Feb 02 12:43:00.346438 2021] [wsgi:error] [pid 32416:tid 140505283548928] [remote 167.248.133.54:38748]   File "/usr/local/lib/python3.6/dist-packages/django/apps/registry.py", line 83, in populate
[Tue Feb 02 12:43:00.346443 2021] [wsgi:error] [pid 32416:tid 140505283548928] [remote 167.248.133.54:38748]     raise RuntimeError("populate() isn't reentrant")
[Tue Feb 02 12:43:00.346508 2021] [wsgi:error] [pid 32416:tid 140505283548928] [remote 167.248.133.54:38748] RuntimeError: populate() isn't reentrant
[Tue Feb 02 12:43:00.457659 2021] [wsgi:error] [pid 32415:tid 140505350690560] [remote 167.248.133.54:32872] mod_wsgi (pid=32415): Target WSGI script '/var/www/HonestyNetwork/HonestyNetwork/wsgi.py' cannot be loaded as Python module.
[Tue Feb 02 12:43:00.457887 2021] [wsgi:error] [pid 32415:tid 140505350690560] [remote 167.248.133.54:32872] mod_wsgi (pid=32415): Exception occurred processing WSGI script '/var/www/HonestyNetwork/HonestyNetwork/wsgi.py'.
[Tue Feb 02 12:43:00.458632 2021] [wsgi:error] [pid 32415:tid 140505350690560] [remote 167.248.133.54:32872] Traceback (most recent call last):
[Tue Feb 02 12:43:00.458719 2021] [wsgi:error] [pid 32415:tid 140505350690560] [remote 167.248.133.54:32872]   File "/var/www/HonestyNetwork/HonestyNetwork/wsgi.py", line 16, in <module>
[Tue Feb 02 12:43:00.458759 2021] [wsgi:error] [pid 32415:tid 140505350690560] [remote 167.248.133.54:32872]     application = get_wsgi_application()
[Tue Feb 02 12:43:00.458779 2021] [wsgi:error] [pid 32415:tid 140505350690560] [remote 167.248.133.54:32872]   File "/usr/local/lib/python3.6/dist-packages/django/core/wsgi.py", line 12, in get_wsgi_application
[Tue Feb 02 12:43:00.458785 2021] [wsgi:error] [pid 32415:tid 140505350690560] [remote 167.248.133.54:32872]     django.setup(set_prefix=False)
[Tue Feb 02 12:43:00.458793 2021] [wsgi:error] [pid 32415:tid 140505350690560] [remote 167.248.133.54:32872]   File "/usr/local/lib/python3.6/dist-packages/django/__init__.py", line 24, in setup
[Tue Feb 02 12:43:00.458798 2021] [wsgi:error] [pid 32415:tid 140505350690560] [remote 167.248.133.54:32872]     apps.populate(settings.INSTALLED_APPS)
[Tue Feb 02 12:43:00.458807 2021] [wsgi:error] [pid 32415:tid 140505350690560] [remote 167.248.133.54:32872]   File "/usr/local/lib/python3.6/dist-packages/django/apps/registry.py", line 83, in populate
[Tue Feb 02 12:43:00.458811 2021] [wsgi:error] [pid 32415:tid 140505350690560] [remote 167.248.133.54:32872]     raise RuntimeError("populate() isn't reentrant")
[Tue Feb 02 12:43:00.458847 2021] [wsgi:error] [pid 32415:tid 140505350690560] [remote 167.248.133.54:32872] RuntimeError: populate() isn't reentrant
[Tue Feb 02 15:26:38.657741 2021] [wsgi:error] [pid 32416:tid 140505182836480] [remote 62.4.14.206:46093] mod_wsgi (pid=32416): Target WSGI script '/var/www/HonestyNetwork/HonestyNetwork/wsgi.py' cannot be loaded as Python module.
[Tue Feb 02 15:26:38.657964 2021] [wsgi:error] [pid 32416:tid 140505182836480] [remote 62.4.14.206:46093] mod_wsgi (pid=32416): Exception occurred processing WSGI script '/var/www/HonestyNetwork/HonestyNetwork/wsgi.py'.
[Tue Feb 02 15:26:38.658570 2021] [wsgi:error] [pid 32416:tid 140505182836480] [remote 62.4.14.206:46093] Traceback (most recent call last):
[Tue Feb 02 15:26:38.658680 2021] [wsgi:error] [pid 32416:tid 140505182836480] [remote 62.4.14.206:46093]   File "/var/www/HonestyNetwork/HonestyNetwork/wsgi.py", line 16, in <module>
[Tue Feb 02 15:26:38.658690 2021] [wsgi:error] [pid 32416:tid 140505182836480] [remote 62.4.14.206:46093]     application = get_wsgi_application()
[Tue Feb 02 15:26:38.658714 2021] [wsgi:error] [pid 32416:tid 140505182836480] [remote 62.4.14.206:46093]   File "/usr/local/lib/python3.6/dist-packages/django/core/wsgi.py", line 12, in get_wsgi_application
[Tue Feb 02 15:26:38.658720 2021] [wsgi:error] [pid 32416:tid 140505182836480] [remote 62.4.14.206:46093]     django.setup(set_prefix=False)
[Tue Feb 02 15:26:38.658731 2021] [wsgi:error] [pid 32416:tid 140505182836480] [remote 62.4.14.206:46093]   File "/usr/local/lib/python3.6/dist-packages/django/__init__.py", line 24, in setup
[Tue Feb 02 15:26:38.658737 2021] [wsgi:error] [pid 32416:tid 140505182836480] [remote 62.4.14.206:46093]     apps.populate(settings.INSTALLED_APPS)
[Tue Feb 02 15:26:38.658745 2021] [wsgi:error] [pid 32416:tid 140505182836480] [remote 62.4.14.206:46093]   File "/usr/local/lib/python3.6/dist-packages/django/apps/registry.py", line 83, in populate
[Tue Feb 02 15:26:38.658750 2021] [wsgi:error] [pid 32416:tid 140505182836480] [remote 62.4.14.206:46093]     raise RuntimeError("populate() isn't reentrant")
[Tue Feb 02 15:26:38.658788 2021] [wsgi:error] [pid 32416:tid 140505182836480] [remote 62.4.14.206:46093] RuntimeError: populate() isn't reentrant
[Tue Feb 02 16:04:37.063380 2021] [wsgi:error] [pid 32415:tid 140505384261376] [remote 104.195.132.229:39484] mod_wsgi (pid=32415): Target WSGI script '/var/www/HonestyNetwork/HonestyNetwork/wsgi.py' cannot be loaded as Python module.
[Tue Feb 02 16:04:37.063665 2021] [wsgi:error] [pid 32415:tid 140505384261376] [remote 104.195.132.229:39484] mod_wsgi (pid=32415): Exception occurred processing WSGI script '/var/www/HonestyNetwork/HonestyNetwork/wsgi.py'.
[Tue Feb 02 16:04:37.064101 2021] [wsgi:error] [pid 32415:tid 140505384261376] [remote 104.195.132.229:39484] Traceback (most recent call last):
[Tue Feb 02 16:04:37.064210 2021] [wsgi:error] [pid 32415:tid 140505384261376] [remote 104.195.132.229:39484]   File "/var/www/HonestyNetwork/HonestyNetwork/wsgi.py", line 16, in <module>
[Tue Feb 02 16:04:37.064218 2021] [wsgi:error] [pid 32415:tid 140505384261376] [remote 104.195.132.229:39484]     application = get_wsgi_application()
[Tue Feb 02 16:04:37.064232 2021] [wsgi:error] [pid 32415:tid 140505384261376] [remote 104.195.132.229:39484]   File "/usr/local/lib/python3.6/dist-packages/django/core/wsgi.py", line 12, in get_wsgi_application
[Tue Feb 02 16:04:37.064236 2021] [wsgi:error] [pid 32415:tid 140505384261376] [remote 104.195.132.229:39484]     django.setup(set_prefix=False)
[Tue Feb 02 16:04:37.064243 2021] [wsgi:error] [pid 32415:tid 140505384261376] [remote 104.195.132.229:39484]   File "/usr/local/lib/python3.6/dist-packages/django/__init__.py", line 24, in setup
[Tue Feb 02 16:04:37.064246 2021] [wsgi:error] [pid 32415:tid 140505384261376] [remote 104.195.132.229:39484]     apps.populate(settings.INSTALLED_APPS)
[Tue Feb 02 16:04:37.064252 2021] [wsgi:error] [pid 32415:tid 140505384261376] [remote 104.195.132.229:39484]   File "/usr/local/lib/python3.6/dist-packages/django/apps/registry.py", line 83, in populate
[Tue Feb 02 16:04:37.064255 2021] [wsgi:error] [pid 32415:tid 140505384261376] [remote 104.195.132.229:39484]     raise RuntimeError("populate() isn't reentrant")
[Tue Feb 02 16:04:37.064288 2021] [wsgi:error] [pid 32415:tid 140505384261376] [remote 104.195.132.229:39484] RuntimeError: populate() isn't reentrant
[Tue Feb 02 16:26:11.278695 2021] [wsgi:error] [pid 32416:tid 140505283548928] [remote 45.155.205.108:44702] mod_wsgi (pid=32416): Target WSGI script '/var/www/HonestyNetwork/HonestyNetwork/wsgi.py' cannot be loaded as Python module.
[Tue Feb 02 16:26:11.278943 2021] [wsgi:error] [pid 32416:tid 140505283548928] [remote 45.155.205.108:44702] mod_wsgi (pid=32416): Exception occurred processing WSGI script '/var/www/HonestyNetwork/HonestyNetwork/wsgi.py'.
[Tue Feb 02 16:26:11.279499 2021] [wsgi:error] [pid 32416:tid 140505283548928] [remote 45.155.205.108:44702] Traceback (most recent call last):
[Tue Feb 02 16:26:11.279600 2021] [wsgi:error] [pid 32416:tid 140505283548928] [remote 45.155.205.108:44702]   File "/var/www/HonestyNetwork/HonestyNetwork/wsgi.py", line 16, in <module>
[Tue Feb 02 16:26:11.279616 2021] [wsgi:error] [pid 32416:tid 140505283548928] [remote 45.155.205.108:44702]     application = get_wsgi_application()
[Tue Feb 02 16:26:11.279649 2021] [wsgi:error] [pid 32416:tid 140505283548928] [remote 45.155.205.108:44702]   File "/usr/local/lib/python3.6/dist-packages/django/core/wsgi.py", line 12, in get_wsgi_application
[Tue Feb 02 16:26:11.279656 2021] [wsgi:error] [pid 32416:tid 140505283548928] [remote 45.155.205.108:44702]     django.setup(set_prefix=False)
[Tue Feb 02 16:26:11.279666 2021] [wsgi:error] [pid 32416:tid 140505283548928] [remote 45.155.205.108:44702]   File "/usr/local/lib/python3.6/dist-packages/django/__init__.py", line 24, in setup
[Tue Feb 02 16:26:11.279672 2021] [wsgi:error] [pid 32416:tid 140505283548928] [remote 45.155.205.108:44702]     apps.populate(settings.INSTALLED_APPS)
[Tue Feb 02 16:26:11.279679 2021] [wsgi:error] [pid 32416:tid 140505283548928] [remote 45.155.205.108:44702]   File "/usr/local/lib/python3.6/dist-packages/django/apps/registry.py", line 83, in populate
[Tue Feb 02 16:26:11.279684 2021] [wsgi:error] [pid 32416:tid 140505283548928] [remote 45.155.205.108:44702]     raise RuntimeError("populate() isn't reentrant")
[Tue Feb 02 16:26:11.279721 2021] [wsgi:error] [pid 32416:tid 140505283548928] [remote 45.155.205.108:44702] RuntimeError: populate() isn't reentrant
[Tue Feb 02 16:26:13.527348 2021] [wsgi:error] [pid 32415:tid 140505350690560] [remote 45.155.205.108:37170] mod_wsgi (pid=32415): Target WSGI script '/var/www/HonestyNetwork/HonestyNetwork/wsgi.py' cannot be loaded as Python module.
[Tue Feb 02 16:26:13.527575 2021] [wsgi:error] [pid 32415:tid 140505350690560] [remote 45.155.205.108:37170] mod_wsgi (pid=32415): Exception occurred processing WSGI script '/var/www/HonestyNetwork/HonestyNetwork/wsgi.py'.
[Tue Feb 02 16:26:13.528130 2021] [wsgi:error] [pid 32415:tid 140505350690560] [remote 45.155.205.108:37170] Traceback (most recent call last):
[Tue Feb 02 16:26:13.528212 2021] [wsgi:error] [pid 32415:tid 140505350690560] [remote 45.155.205.108:37170]   File "/var/www/HonestyNetwork/HonestyNetwork/wsgi.py", line 16, in <module>
[Tue Feb 02 16:26:13.528227 2021] [wsgi:error] [pid 32415:tid 140505350690560] [remote 45.155.205.108:37170]     application = get_wsgi_application()
[Tue Feb 02 16:26:13.528248 2021] [wsgi:error] [pid 32415:tid 140505350690560] [remote 45.155.205.108:37170]   File "/usr/local/lib/python3.6/dist-packages/django/core/wsgi.py", line 12, in get_wsgi_application
[Tue Feb 02 16:26:13.528254 2021] [wsgi:error] [pid 32415:tid 140505350690560] [remote 45.155.205.108:37170]     django.setup(set_prefix=False)
[Tue Feb 02 16:26:13.528264 2021] [wsgi:error] [pid 32415:tid 140505350690560] [remote 45.155.205.108:37170]   File "/usr/local/lib/python3.6/dist-packages/django/__init__.py", line 24, in setup
[Tue Feb 02 16:26:13.528268 2021] [wsgi:error] [pid 32415:tid 140505350690560] [remote 45.155.205.108:37170]     apps.populate(settings.INSTALLED_APPS)
[Tue Feb 02 16:26:13.528277 2021] [wsgi:error] [pid 32415:tid 140505350690560] [remote 45.155.205.108:37170]   File "/usr/local/lib/python3.6/dist-packages/django/apps/registry.py", line 83, in populate
[Tue Feb 02 16:26:13.528281 2021] [wsgi:error] [pid 32415:tid 140505350690560] [remote 45.155.205.108:37170]     raise RuntimeError("populate() isn't reentrant")
[Tue Feb 02 16:26:13.528325 2021] [wsgi:error] [pid 32415:tid 140505350690560] [remote 45.155.205.108:37170] RuntimeError: populate() isn't reentrant
[Tue Feb 02 16:26:14.353936 2021] [wsgi:error] [pid 32416:tid 140505182836480] [remote 45.155.205.108:44506] mod_wsgi (pid=32416): Target WSGI script '/var/www/HonestyNetwork/HonestyNetwork/wsgi.py' cannot be loaded as Python module.
[Tue Feb 02 16:26:14.354051 2021] [wsgi:error] [pid 32416:tid 140505182836480] [remote 45.155.205.108:44506] mod_wsgi (pid=32416): Exception occurred processing WSGI script '/var/www/HonestyNetwork/HonestyNetwork/wsgi.py'.
[Tue Feb 02 16:26:14.354255 2021] [wsgi:error] [pid 32416:tid 140505182836480] [remote 45.155.205.108:44506] Traceback (most recent call last):
[Tue Feb 02 16:26:14.354323 2021] [wsgi:error] [pid 32416:tid 140505182836480] [remote 45.155.205.108:44506]   File "/var/www/HonestyNetwork/HonestyNetwork/wsgi.py", line 16, in <module>
[Tue Feb 02 16:26:14.354330 2021] [wsgi:error] [pid 32416:tid 140505182836480] [remote 45.155.205.108:44506]     application = get_wsgi_application()
[Tue Feb 02 16:26:14.354340 2021] [wsgi:error] [pid 32416:tid 140505182836480] [remote 45.155.205.108:44506]   File "/usr/local/lib/python3.6/dist-packages/django/core/wsgi.py", line 12, in get_wsgi_application
[Tue Feb 02 16:26:14.354345 2021] [wsgi:error] [pid 32416:tid 140505182836480] [remote 45.155.205.108:44506]     django.setup(set_prefix=False)
[Tue Feb 02 16:26:14.354354 2021] [wsgi:error] [pid 32416:tid 140505182836480] [remote 45.155.205.108:44506]   File "/usr/local/lib/python3.6/dist-packages/django/__init__.py", line 24, in setup
[Tue Feb 02 16:26:14.354358 2021] [wsgi:error] [pid 32416:tid 140505182836480] [remote 45.155.205.108:44506]     apps.populate(settings.INSTALLED_APPS)
[Tue Feb 02 16:26:14.354367 2021] [wsgi:error] [pid 32416:tid 140505182836480] [remote 45.155.205.108:44506]   File "/usr/local/lib/python3.6/dist-packages/django/apps/registry.py", line 83, in populate
[Tue Feb 02 16:26:14.354372 2021] [wsgi:error] [pid 32416:tid 140505182836480] [remote 45.155.205.108:44506]     raise RuntimeError("populate() isn't reentrant")
[Tue Feb 02 16:26:14.354393 2021] [wsgi:error] [pid 32416:tid 140505182836480] [remote 45.155.205.108:44506] RuntimeError: populate() isn't reentrant
[Tue Feb 02 16:26:17.302489 2021] [wsgi:error] [pid 32415:tid 140505384261376] [remote 45.155.205.108:37530] mod_wsgi (pid=32415): Target WSGI script '/var/www/HonestyNetwork/HonestyNetwork/wsgi.py' cannot be loaded as Python module.
[Tue Feb 02 16:26:17.302584 2021] [wsgi:error] [pid 32415:tid 140505384261376] [remote 45.155.205.108:37530] mod_wsgi (pid=32415): Exception occurred processing WSGI script '/var/www/HonestyNetwork/HonestyNetwork/wsgi.py'.
[Tue Feb 02 16:26:17.302728 2021] [wsgi:error] [pid 32415:tid 140505384261376] [remote 45.155.205.108:37530] Traceback (most recent call last):
[Tue Feb 02 16:26:17.302777 2021] [wsgi:error] [pid 32415:tid 140505384261376] [remote 45.155.205.108:37530]   File "/var/www/HonestyNetwork/HonestyNetwork/wsgi.py", line 16, in <module>
[Tue Feb 02 16:26:17.302782 2021] [wsgi:error] [pid 32415:tid 140505384261376] [remote 45.155.205.108:37530]     application = get_wsgi_application()
[Tue Feb 02 16:26:17.302790 2021] [wsgi:error] [pid 32415:tid 140505384261376] [remote 45.155.205.108:37530]   File "/usr/local/lib/python3.6/dist-packages/django/core/wsgi.py", line 12, in get_wsgi_application
[Tue Feb 02 16:26:17.302793 2021] [wsgi:error] [pid 32415:tid 140505384261376] [remote 45.155.205.108:37530]     django.setup(set_prefix=False)
[Tue Feb 02 16:26:17.302799 2021] [wsgi:error] [pid 32415:tid 140505384261376] [remote 45.155.205.108:37530]   File "/usr/local/lib/python3.6/dist-packages/django/__init__.py", line 24, in setup
[Tue Feb 02 16:26:17.302802 2021] [wsgi:error] [pid 32415:tid 140505384261376] [remote 45.155.205.108:37530]     apps.populate(settings.INSTALLED_APPS)
[Tue Feb 02 16:26:17.302809 2021] [wsgi:error] [pid 32415:tid 140505384261376] [remote 45.155.205.108:37530]   File "/usr/local/lib/python3.6/dist-packages/django/apps/registry.py", line 83, in populate
[Tue Feb 02 16:26:17.302812 2021] [wsgi:error] [pid 32415:tid 140505384261376] [remote 45.155.205.108:37530]     raise RuntimeError("populate() isn't reentrant")
[Tue Feb 02 16:26:17.302828 2021] [wsgi:error] [pid 32415:tid 140505384261376] [remote 45.155.205.108:37530] RuntimeError: populate() isn't reentrant
[Tue Feb 02 16:26:17.406565 2021] [wsgi:error] [pid 32416:tid 140505283548928] [remote 45.155.205.108:49366] mod_wsgi (pid=32416): Target WSGI script '/var/www/HonestyNetwork/HonestyNetwork/wsgi.py' cannot be loaded as Python module.
[Tue Feb 02 16:26:17.406723 2021] [wsgi:error] [pid 32416:tid 140505283548928] [remote 45.155.205.108:49366] mod_wsgi (pid=32416): Exception occurred processing WSGI script '/var/www/HonestyNetwork/HonestyNetwork/wsgi.py'.
[Tue Feb 02 16:26:17.406986 2021] [wsgi:error] [pid 32416:tid 140505283548928] [remote 45.155.205.108:49366] Traceback (most recent call last):
[Tue Feb 02 16:26:17.407057 2021] [wsgi:error] [pid 32416:tid 140505283548928] [remote 45.155.205.108:49366]   File "/var/www/HonestyNetwork/HonestyNetwork/wsgi.py", line 16, in <module>
[Tue Feb 02 16:26:17.407072 2021] [wsgi:error] [pid 32416:tid 140505283548928] [remote 45.155.205.108:49366]     application = get_wsgi_application()
[Tue Feb 02 16:26:17.407100 2021] [wsgi:error] [pid 32416:tid 140505283548928] [remote 45.155.205.108:49366]   File "/usr/local/lib/python3.6/dist-packages/django/core/wsgi.py", line 12, in get_wsgi_application
[Tue Feb 02 16:26:17.407110 2021] [wsgi:error] [pid 32416:tid 140505283548928] [remote 45.155.205.108:49366]     django.setup(set_prefix=False)
[Tue Feb 02 16:26:17.407120 2021] [wsgi:error] [pid 32416:tid 140505283548928] [remote 45.155.205.108:49366]   File "/usr/local/lib/python3.6/dist-packages/django/__init__.py", line 24, in setup
[Tue Feb 02 16:26:17.407124 2021] [wsgi:error] [pid 32416:tid 140505283548928] [remote 45.155.205.108:49366]     apps.populate(settings.INSTALLED_APPS)
[Tue Feb 02 16:26:17.407131 2021] [wsgi:error] [pid 32416:tid 140505283548928] [remote 45.155.205.108:49366]   File "/usr/local/lib/python3.6/dist-packages/django/apps/registry.py", line 83, in populate
[Tue Feb 02 16:26:17.407135 2021] [wsgi:error] [pid 32416:tid 140505283548928] [remote 45.155.205.108:49366]     raise RuntimeError("populate() isn't reentrant")
[Tue Feb 02 16:26:17.407163 2021] [wsgi:error] [pid 32416:tid 140505283548928] [remote 45.155.205.108:49366] RuntimeError: populate() isn't reentrant
[Tue Feb 02 16:26:17.743920 2021] [wsgi:error] [pid 32415:tid 140505350690560] [remote 45.155.205.108:50092] mod_wsgi (pid=32415): Target WSGI script '/var/www/HonestyNetwork/HonestyNetwork/wsgi.py' cannot be loaded as Python module.
[Tue Feb 02 16:26:17.744009 2021] [wsgi:error] [pid 32415:tid 140505350690560] [remote 45.155.205.108:50092] mod_wsgi (pid=32415): Exception occurred processing WSGI script '/var/www/HonestyNetwork/HonestyNetwork/wsgi.py'.
[Tue Feb 02 16:26:17.744223 2021] [wsgi:error] [pid 32415:tid 140505350690560] [remote 45.155.205.108:50092] Traceback (most recent call last):
[Tue Feb 02 16:26:17.744284 2021] [wsgi:error] [pid 32415:tid 140505350690560] [remote 45.155.205.108:50092]   File "/var/www/HonestyNetwork/HonestyNetwork/wsgi.py", line 16, in <module>
[Tue Feb 02 16:26:17.744293 2021] [wsgi:error] [pid 32415:tid 140505350690560] [remote 45.155.205.108:50092]     application = get_wsgi_application()
[Tue Feb 02 16:26:17.744305 2021] [wsgi:error] [pid 32415:tid 140505350690560] [remote 45.155.205.108:50092]   File "/usr/local/lib/python3.6/dist-packages/django/core/wsgi.py", line 12, in get_wsgi_application
[Tue Feb 02 16:26:17.744310 2021] [wsgi:error] [pid 32415:tid 140505350690560] [remote 45.155.205.108:50092]     django.setup(set_prefix=False)
[Tue Feb 02 16:26:17.744318 2021] [wsgi:error] [pid 32415:tid 140505350690560] [remote 45.155.205.108:50092]   File "/usr/local/lib/python3.6/dist-packages/django/__init__.py", line 24, in setup
[Tue Feb 02 16:26:17.744322 2021] [wsgi:error] [pid 32415:tid 140505350690560] [remote 45.155.205.108:50092]     apps.populate(settings.INSTALLED_APPS)
[Tue Feb 02 16:26:17.744330 2021] [wsgi:error] [pid 32415:tid 140505350690560] [remote 45.155.205.108:50092]   File "/usr/local/lib/python3.6/dist-packages/django/apps/registry.py", line 83, in populate
[Tue Feb 02 16:26:17.744335 2021] [wsgi:error] [pid 32415:tid 140505350690560] [remote 45.155.205.108:50092]     raise RuntimeError("populate() isn't reentrant")
[Tue Feb 02 16:26:17.744357 2021] [wsgi:error] [pid 32415:tid 140505350690560] [remote 45.155.205.108:50092] RuntimeError: populate() isn't reentrant
[Tue Feb 02 16:26:19.884881 2021] [wsgi:error] [pid 32416:tid 140505182836480] [remote 45.155.205.108:57516] mod_wsgi (pid=32416): Target WSGI script '/var/www/HonestyNetwork/HonestyNetwork/wsgi.py' cannot be loaded as Python module.
[Tue Feb 02 16:26:19.885350 2021] [wsgi:error] [pid 32416:tid 140505182836480] [remote 45.155.205.108:57516] mod_wsgi (pid=32416): Exception occurred processing WSGI script '/var/www/HonestyNetwork/HonestyNetwork/wsgi.py'.
[Tue Feb 02 16:26:19.885570 2021] [wsgi:error] [pid 32416:tid 140505182836480] [remote 45.155.205.108:57516] Traceback (most recent call last):
[Tue Feb 02 16:26:19.885629 2021] [wsgi:error] [pid 32416:tid 140505182836480] [remote 45.155.205.108:57516]   File "/var/www/HonestyNetwork/HonestyNetwork/wsgi.py", line 16, in <module>
[Tue Feb 02 16:26:19.885637 2021] [wsgi:error] [pid 32416:tid 140505182836480] [remote 45.155.205.108:57516]     application = get_wsgi_application()
[Tue Feb 02 16:26:19.885648 2021] [wsgi:error] [pid 32416:tid 140505182836480] [remote 45.155.205.108:57516]   File "/usr/local/lib/python3.6/dist-packages/django/core/wsgi.py", line 12, in get_wsgi_application
[Tue Feb 02 16:26:19.885652 2021] [wsgi:error] [pid 32416:tid 140505182836480] [remote 45.155.205.108:57516]     django.setup(set_prefix=False)
[Tue Feb 02 16:26:19.885662 2021] [wsgi:error] [pid 32416:tid 140505182836480] [remote 45.155.205.108:57516]   File "/usr/local/lib/python3.6/dist-packages/django/__init__.py", line 24, in setup
[Tue Feb 02 16:26:19.885667 2021] [wsgi:error] [pid 32416:tid 140505182836480] [remote 45.155.205.108:57516]     apps.populate(settings.INSTALLED_APPS)
[Tue Feb 02 16:26:19.885675 2021] [wsgi:error] [pid 32416:tid 140505182836480] [remote 45.155.205.108:57516]   File "/usr/local/lib/python3.6/dist-packages/django/apps/registry.py", line 83, in populate
[Tue Feb 02 16:26:19.885680 2021] [wsgi:error] [pid 32416:tid 140505182836480] [remote 45.155.205.108:57516]     raise RuntimeError("populate() isn't reentrant")
[Tue Feb 02 16:26:19.885727 2021] [wsgi:error] [pid 32416:tid 140505182836480] [remote 45.155.205.108:57516] RuntimeError: populate() isn't reentrant
[Tue Feb 02 16:26:19.912201 2021] [wsgi:error] [pid 32415:tid 140505384261376] [remote 45.155.205.108:38340] mod_wsgi (pid=32415): Target WSGI script '/var/www/HonestyNetwork/HonestyNetwork/wsgi.py' cannot be loaded as Python module.
[Tue Feb 02 16:26:19.912295 2021] [wsgi:error] [pid 32415:tid 140505384261376] [remote 45.155.205.108:38340] mod_wsgi (pid=32415): Exception occurred processing WSGI script '/var/www/HonestyNetwork/HonestyNetwork/wsgi.py'.
[Tue Feb 02 16:26:19.912485 2021] [wsgi:error] [pid 32415:tid 140505384261376] [remote 45.155.205.108:38340] Traceback (most recent call last):
[Tue Feb 02 16:26:19.912540 2021] [wsgi:error] [pid 32415:tid 140505384261376] [remote 45.155.205.108:38340]   File "/var/www/HonestyNetwork/HonestyNetwork/wsgi.py", line 16, in <module>
[Tue Feb 02 16:26:19.912547 2021] [wsgi:error] [pid 32415:tid 140505384261376] [remote 45.155.205.108:38340]     application = get_wsgi_application()
[Tue Feb 02 16:26:19.912557 2021] [wsgi:error] [pid 32415:tid 140505384261376] [remote 45.155.205.108:38340]   File "/usr/local/lib/python3.6/dist-packages/django/core/wsgi.py", line 12, in get_wsgi_application
[Tue Feb 02 16:26:19.912562 2021] [wsgi:error] [pid 32415:tid 140505384261376] [remote 45.155.205.108:38340]     django.setup(set_prefix=False)
[Tue Feb 02 16:26:19.912570 2021] [wsgi:error] [pid 32415:tid 140505384261376] [remote 45.155.205.108:38340]   File "/usr/local/lib/python3.6/dist-packages/django/__init__.py", line 24, in setup
[Tue Feb 02 16:26:19.912574 2021] [wsgi:error] [pid 32415:tid 140505384261376] [remote 45.155.205.108:38340]     apps.populate(settings.INSTALLED_APPS)
[Tue Feb 02 16:26:19.912583 2021] [wsgi:error] [pid 32415:tid 140505384261376] [remote 45.155.205.108:38340]   File "/usr/local/lib/python3.6/dist-packages/django/apps/registry.py", line 83, in populate
[Tue Feb 02 16:26:19.912587 2021] [wsgi:error] [pid 32415:tid 140505384261376] [remote 45.155.205.108:38340]     raise RuntimeError("populate() isn't reentrant")
[Tue Feb 02 16:26:19.912608 2021] [wsgi:error] [pid 32415:tid 140505384261376] [remote 45.155.205.108:38340] RuntimeError: populate() isn't reentrant
[Tue Feb 02 16:26:23.910556 2021] [wsgi:error] [pid 32415:tid 140505350690560] [remote 45.155.205.108:41060] mod_wsgi (pid=32415): Target WSGI script '/var/www/HonestyNetwork/HonestyNetwork/wsgi.py' cannot be loaded as Python module.
[Tue Feb 02 16:26:23.910677 2021] [wsgi:error] [pid 32415:tid 140505350690560] [remote 45.155.205.108:41060] mod_wsgi (pid=32415): Exception occurred processing WSGI script '/var/www/HonestyNetwork/HonestyNetwork/wsgi.py'.
[Tue Feb 02 16:26:23.910885 2021] [wsgi:error] [pid 32415:tid 140505350690560] [remote 45.155.205.108:41060] Traceback (most recent call last):
[Tue Feb 02 16:26:23.910943 2021] [wsgi:error] [pid 32415:tid 140505350690560] [remote 45.155.205.108:41060]   File "/var/www/HonestyNetwork/HonestyNetwork/wsgi.py", line 16, in <module>
[Tue Feb 02 16:26:23.910952 2021] [wsgi:error] [pid 32415:tid 140505350690560] [remote 45.155.205.108:41060]     application = get_wsgi_application()
[Tue Feb 02 16:26:23.910965 2021] [wsgi:error] [pid 32415:tid 140505350690560] [remote 45.155.205.108:41060]   File "/usr/local/lib/python3.6/dist-packages/django/core/wsgi.py", line 12, in get_wsgi_application
[Tue Feb 02 16:26:23.910970 2021] [wsgi:error] [pid 32415:tid 140505350690560] [remote 45.155.205.108:41060]     django.setup(set_prefix=False)
[Tue Feb 02 16:26:23.910980 2021] [wsgi:error] [pid 32415:tid 140505350690560] [remote 45.155.205.108:41060]   File "/usr/local/lib/python3.6/dist-packages/django/__init__.py", line 24, in setup
[Tue Feb 02 16:26:23.910984 2021] [wsgi:error] [pid 32415:tid 140505350690560] [remote 45.155.205.108:41060]     apps.populate(settings.INSTALLED_APPS)
[Tue Feb 02 16:26:23.910991 2021] [wsgi:error] [pid 32415:tid 140505350690560] [remote 45.155.205.108:41060]   File "/usr/local/lib/python3.6/dist-packages/django/apps/registry.py", line 83, in populate
[Tue Feb 02 16:26:23.911015 2021] [wsgi:error] [pid 32415:tid 140505350690560] [remote 45.155.205.108:41060]     raise RuntimeError("populate() isn't reentrant")
[Tue Feb 02 16:26:23.911038 2021] [wsgi:error] [pid 32415:tid 140505350690560] [remote 45.155.205.108:41060] RuntimeError: populate() isn't reentrant
[Tue Feb 02 16:26:24.021789 2021] [wsgi:error] [pid 32416:tid 140505283548928] [remote 45.155.205.108:41720] mod_wsgi (pid=32416): Target WSGI script '/var/www/HonestyNetwork/HonestyNetwork/wsgi.py' cannot be loaded as Python module.
[Tue Feb 02 16:26:24.021920 2021] [wsgi:error] [pid 32416:tid 140505283548928] [remote 45.155.205.108:41720] mod_wsgi (pid=32416): Exception occurred processing WSGI script '/var/www/HonestyNetwork/HonestyNetwork/wsgi.py'.
[Tue Feb 02 16:26:24.022137 2021] [wsgi:error] [pid 32416:tid 140505283548928] [remote 45.155.205.108:41720] Traceback (most recent call last):
[Tue Feb 02 16:26:24.022186 2021] [wsgi:error] [pid 32416:tid 140505283548928] [remote 45.155.205.108:41720]   File "/var/www/HonestyNetwork/HonestyNetwork/wsgi.py", line 16, in <module>
[Tue Feb 02 16:26:24.022192 2021] [wsgi:error] [pid 32416:tid 140505283548928] [remote 45.155.205.108:41720]     application = get_wsgi_application()
[Tue Feb 02 16:26:24.022201 2021] [wsgi:error] [pid 32416:tid 140505283548928] [remote 45.155.205.108:41720]   File "/usr/local/lib/python3.6/dist-packages/django/core/wsgi.py", line 12, in get_wsgi_application
[Tue Feb 02 16:26:24.022204 2021] [wsgi:error] [pid 32416:tid 140505283548928] [remote 45.155.205.108:41720]     django.setup(set_prefix=False)
[Tue Feb 02 16:26:24.022211 2021] [wsgi:error] [pid 32416:tid 140505283548928] [remote 45.155.205.108:41720]   File "/usr/local/lib/python3.6/dist-packages/django/__init__.py", line 24, in setup
[Tue Feb 02 16:26:24.022214 2021] [wsgi:error] [pid 32416:tid 140505283548928] [remote 45.155.205.108:41720]     apps.populate(settings.INSTALLED_APPS)
[Tue Feb 02 16:26:24.022221 2021] [wsgi:error] [pid 32416:tid 140505283548928] [remote 45.155.205.108:41720]   File "/usr/local/lib/python3.6/dist-packages/django/apps/registry.py", line 83, in populate
[Tue Feb 02 16:26:24.022224 2021] [wsgi:error] [pid 32416:tid 140505283548928] [remote 45.155.205.108:41720]     raise RuntimeError("populate() isn't reentrant")
[Tue Feb 02 16:26:24.022244 2021] [wsgi:error] [pid 32416:tid 140505283548928] [remote 45.155.205.108:41720] RuntimeError: populate() isn't reentrant
[Tue Feb 02 17:13:33.381678 2021] [wsgi:error] [pid 32416:tid 140505182836480] [remote 194.48.199.78:45134] mod_wsgi (pid=32416): Target WSGI script '/var/www/HonestyNetwork/HonestyNetwork/wsgi.py' cannot be loaded as Python module.
[Tue Feb 02 17:13:33.381864 2021] [wsgi:error] [pid 32416:tid 140505182836480] [remote 194.48.199.78:45134] mod_wsgi (pid=32416): Exception occurred processing WSGI script '/var/www/HonestyNetwork/HonestyNetwork/wsgi.py'.
[Tue Feb 02 17:13:33.382331 2021] [wsgi:error] [pid 32416:tid 140505182836480] [remote 194.48.199.78:45134] Traceback (most recent call last):
[Tue Feb 02 17:13:33.382411 2021] [wsgi:error] [pid 32416:tid 140505182836480] [remote 194.48.199.78:45134]   File "/var/www/HonestyNetwork/HonestyNetwork/wsgi.py", line 16, in <module>
[Tue Feb 02 17:13:33.382417 2021] [wsgi:error] [pid 32416:tid 140505182836480] [remote 194.48.199.78:45134]     application = get_wsgi_application()
[Tue Feb 02 17:13:33.382435 2021] [wsgi:error] [pid 32416:tid 140505182836480] [remote 194.48.199.78:45134]   File "/usr/local/lib/python3.6/dist-packages/django/core/wsgi.py", line 12, in get_wsgi_application
[Tue Feb 02 17:13:33.382439 2021] [wsgi:error] [pid 32416:tid 140505182836480] [remote 194.48.199.78:45134]     django.setup(set_prefix=False)
[Tue Feb 02 17:13:33.382447 2021] [wsgi:error] [pid 32416:tid 140505182836480] [remote 194.48.199.78:45134]   File "/usr/local/lib/python3.6/dist-packages/django/__init__.py", line 24, in setup
[Tue Feb 02 17:13:33.382466 2021] [wsgi:error] [pid 32416:tid 140505182836480] [remote 194.48.199.78:45134]     apps.populate(settings.INSTALLED_APPS)
[Tue Feb 02 17:13:33.382474 2021] [wsgi:error] [pid 32416:tid 140505182836480] [remote 194.48.199.78:45134]   File "/usr/local/lib/python3.6/dist-packages/django/apps/registry.py", line 83, in populate
[Tue Feb 02 17:13:33.382477 2021] [wsgi:error] [pid 32416:tid 140505182836480] [remote 194.48.199.78:45134]     raise RuntimeError("populate() isn't reentrant")
[Tue Feb 02 17:13:33.382510 2021] [wsgi:error] [pid 32416:tid 140505182836480] [remote 194.48.199.78:45134] RuntimeError: populate() isn't reentrant
[Tue Feb 02 18:48:33.350993 2021] [wsgi:error] [pid 32415:tid 140505384261376] [remote 102.165.30.49:34000] mod_wsgi (pid=32415): Target WSGI script '/var/www/HonestyNetwork/HonestyNetwork/wsgi.py' cannot be loaded as Python module.
[Tue Feb 02 18:48:33.351242 2021] [wsgi:error] [pid 32415:tid 140505384261376] [remote 102.165.30.49:34000] mod_wsgi (pid=32415): Exception occurred processing WSGI script '/var/www/HonestyNetwork/HonestyNetwork/wsgi.py'.
[Tue Feb 02 18:48:33.351754 2021] [wsgi:error] [pid 32415:tid 140505384261376] [remote 102.165.30.49:34000] Traceback (most recent call last):
[Tue Feb 02 18:48:33.351844 2021] [wsgi:error] [pid 32415:tid 140505384261376] [remote 102.165.30.49:34000]   File "/var/www/HonestyNetwork/HonestyNetwork/wsgi.py", line 16, in <module>
[Tue Feb 02 18:48:33.351853 2021] [wsgi:error] [pid 32415:tid 140505384261376] [remote 102.165.30.49:34000]     application = get_wsgi_application()
[Tue Feb 02 18:48:33.351871 2021] [wsgi:error] [pid 32415:tid 140505384261376] [remote 102.165.30.49:34000]   File "/usr/local/lib/python3.6/dist-packages/django/core/wsgi.py", line 12, in get_wsgi_application
[Tue Feb 02 18:48:33.351877 2021] [wsgi:error] [pid 32415:tid 140505384261376] [remote 102.165.30.49:34000]     django.setup(set_prefix=False)
[Tue Feb 02 18:48:33.351886 2021] [wsgi:error] [pid 32415:tid 140505384261376] [remote 102.165.30.49:34000]   File "/usr/local/lib/python3.6/dist-packages/django/__init__.py", line 24, in setup
[Tue Feb 02 18:48:33.351891 2021] [wsgi:error] [pid 32415:tid 140505384261376] [remote 102.165.30.49:34000]     apps.populate(settings.INSTALLED_APPS)
[Tue Feb 02 18:48:33.351899 2021] [wsgi:error] [pid 32415:tid 140505384261376] [remote 102.165.30.49:34000]   File "/usr/local/lib/python3.6/dist-packages/django/apps/registry.py", line 83, in populate
[Tue Feb 02 18:48:33.351904 2021] [wsgi:error] [pid 32415:tid 140505384261376] [remote 102.165.30.49:34000]     raise RuntimeError("populate() isn't reentrant")
[Tue Feb 02 18:48:33.351945 2021] [wsgi:error] [pid 32415:tid 140505384261376] [remote 102.165.30.49:34000] RuntimeError: populate() isn't reentrant
[Tue Feb 02 19:38:54.462046 2021] [wsgi:error] [pid 32416:tid 140505283548928] [remote 104.195.132.229:64163] mod_wsgi (pid=32416): Target WSGI script '/var/www/HonestyNetwork/HonestyNetwork/wsgi.py' cannot be loaded as Python module.
[Tue Feb 02 19:38:54.462183 2021] [wsgi:error] [pid 32416:tid 140505283548928] [remote 104.195.132.229:64163] mod_wsgi (pid=32416): Exception occurred processing WSGI script '/var/www/HonestyNetwork/HonestyNetwork/wsgi.py'.
[Tue Feb 02 19:38:54.462716 2021] [wsgi:error] [pid 32416:tid 140505283548928] [remote 104.195.132.229:64163] Traceback (most recent call last):
[Tue Feb 02 19:38:54.462785 2021] [wsgi:error] [pid 32416:tid 140505283548928] [remote 104.195.132.229:64163]   File "/var/www/HonestyNetwork/HonestyNetwork/wsgi.py", line 16, in <module>
[Tue Feb 02 19:38:54.462794 2021] [wsgi:error] [pid 32416:tid 140505283548928] [remote 104.195.132.229:64163]     application = get_wsgi_application()
[Tue Feb 02 19:38:54.462814 2021] [wsgi:error] [pid 32416:tid 140505283548928] [remote 104.195.132.229:64163]   File "/usr/local/lib/python3.6/dist-packages/django/core/wsgi.py", line 12, in get_wsgi_application
[Tue Feb 02 19:38:54.462818 2021] [wsgi:error] [pid 32416:tid 140505283548928] [remote 104.195.132.229:64163]     django.setup(set_prefix=False)
[Tue Feb 02 19:38:54.462837 2021] [wsgi:error] [pid 32416:tid 140505283548928] [remote 104.195.132.229:64163]   File "/usr/local/lib/python3.6/dist-packages/django/__init__.py", line 24, in setup
[Tue Feb 02 19:38:54.462840 2021] [wsgi:error] [pid 32416:tid 140505283548928] [remote 104.195.132.229:64163]     apps.populate(settings.INSTALLED_APPS)
[Tue Feb 02 19:38:54.462846 2021] [wsgi:error] [pid 32416:tid 140505283548928] [remote 104.195.132.229:64163]   File "/usr/local/lib/python3.6/dist-packages/django/apps/registry.py", line 83, in populate
[Tue Feb 02 19:38:54.462849 2021] [wsgi:error] [pid 32416:tid 140505283548928] [remote 104.195.132.229:64163]     raise RuntimeError("populate() isn't reentrant")
[Tue Feb 02 19:38:54.462881 2021] [wsgi:error] [pid 32416:tid 140505283548928] [remote 104.195.132.229:64163] RuntimeError: populate() isn't reentrant
[Tue Feb 02 19:39:04.508160 2021] [wsgi:error] [pid 32415:tid 140505350690560] [remote 104.195.132.229:64170] mod_wsgi (pid=32415): Target WSGI script '/var/www/HonestyNetwork/HonestyNetwork/wsgi.py' cannot be loaded as Python module.
[Tue Feb 02 19:39:04.508718 2021] [wsgi:error] [pid 32415:tid 140505350690560] [remote 104.195.132.229:64170] mod_wsgi (pid=32415): Exception occurred processing WSGI script '/var/www/HonestyNetwork/HonestyNetwork/wsgi.py'.
[Tue Feb 02 19:39:04.509132 2021] [wsgi:error] [pid 32415:tid 140505350690560] [remote 104.195.132.229:64170] Traceback (most recent call last):
[Tue Feb 02 19:39:04.509187 2021] [wsgi:error] [pid 32415:tid 140505350690560] [remote 104.195.132.229:64170]   File "/var/www/HonestyNetwork/HonestyNetwork/wsgi.py", line 16, in <module>
[Tue Feb 02 19:39:04.509223 2021] [wsgi:error] [pid 32415:tid 140505350690560] [remote 104.195.132.229:64170]     application = get_wsgi_application()
[Tue Feb 02 19:39:04.509241 2021] [wsgi:error] [pid 32415:tid 140505350690560] [remote 104.195.132.229:64170]   File "/usr/local/lib/python3.6/dist-packages/django/core/wsgi.py", line 12, in get_wsgi_application
[Tue Feb 02 19:39:04.509246 2021] [wsgi:error] [pid 32415:tid 140505350690560] [remote 104.195.132.229:64170]     django.setup(set_prefix=False)
[Tue Feb 02 19:39:04.509253 2021] [wsgi:error] [pid 32415:tid 140505350690560] [remote 104.195.132.229:64170]   File "/usr/local/lib/python3.6/dist-packages/django/__init__.py", line 24, in setup
[Tue Feb 02 19:39:04.509256 2021] [wsgi:error] [pid 32415:tid 140505350690560] [remote 104.195.132.229:64170]     apps.populate(settings.INSTALLED_APPS)
[Tue Feb 02 19:39:04.509263 2021] [wsgi:error] [pid 32415:tid 140505350690560] [remote 104.195.132.229:64170]   File "/usr/local/lib/python3.6/dist-packages/django/apps/registry.py", line 83, in populate
[Tue Feb 02 19:39:04.509266 2021] [wsgi:error] [pid 32415:tid 140505350690560] [remote 104.195.132.229:64170]     raise RuntimeError("populate() isn't reentrant")
[Tue Feb 02 19:39:04.509298 2021] [wsgi:error] [pid 32415:tid 140505350690560] [remote 104.195.132.229:64170] RuntimeError: populate() isn't reentrant
[Tue Feb 02 19:39:05.446910 2021] [wsgi:error] [pid 32416:tid 140505182836480] [remote 104.195.132.229:64171] mod_wsgi (pid=32416): Target WSGI script '/var/www/HonestyNetwork/HonestyNetwork/wsgi.py' cannot be loaded as Python module.
[Tue Feb 02 19:39:05.446990 2021] [wsgi:error] [pid 32416:tid 140505182836480] [remote 104.195.132.229:64171] mod_wsgi (pid=32416): Exception occurred processing WSGI script '/var/www/HonestyNetwork/HonestyNetwork/wsgi.py'.
[Tue Feb 02 19:39:05.447148 2021] [wsgi:error] [pid 32416:tid 140505182836480] [remote 104.195.132.229:64171] Traceback (most recent call last):
[Tue Feb 02 19:39:05.447198 2021] [wsgi:error] [pid 32416:tid 140505182836480] [remote 104.195.132.229:64171]   File "/var/www/HonestyNetwork/HonestyNetwork/wsgi.py", line 16, in <module>
[Tue Feb 02 19:39:05.447203 2021] [wsgi:error] [pid 32416:tid 140505182836480] [remote 104.195.132.229:64171]     application = get_wsgi_application()
[Tue Feb 02 19:39:05.447212 2021] [wsgi:error] [pid 32416:tid 140505182836480] [remote 104.195.132.229:64171]   File "/usr/local/lib/python3.6/dist-packages/django/core/wsgi.py", line 12, in get_wsgi_application
[Tue Feb 02 19:39:05.447231 2021] [wsgi:error] [pid 32416:tid 140505182836480] [remote 104.195.132.229:64171]     django.setup(set_prefix=False)
[Tue Feb 02 19:39:05.447238 2021] [wsgi:error] [pid 32416:tid 140505182836480] [remote 104.195.132.229:64171]   File "/usr/local/lib/python3.6/dist-packages/django/__init__.py", line 24, in setup
[Tue Feb 02 19:39:05.447242 2021] [wsgi:error] [pid 32416:tid 140505182836480] [remote 104.195.132.229:64171]     apps.populate(settings.INSTALLED_APPS)
[Tue Feb 02 19:39:05.447248 2021] [wsgi:error] [pid 32416:tid 140505182836480] [remote 104.195.132.229:64171]   File "/usr/local/lib/python3.6/dist-packages/django/apps/registry.py", line 83, in populate
[Tue Feb 02 19:39:05.447251 2021] [wsgi:error] [pid 32416:tid 140505182836480] [remote 104.195.132.229:64171]     raise RuntimeError("populate() isn't reentrant")
[Tue Feb 02 19:39:05.447275 2021] [wsgi:error] [pid 32416:tid 140505182836480] [remote 104.195.132.229:64171] RuntimeError: populate() isn't reentrant
[Tue Feb 02 19:39:06.059824 2021] [wsgi:error] [pid 32415:tid 140505384261376] [remote 104.195.132.229:64173] mod_wsgi (pid=32415): Target WSGI script '/var/www/HonestyNetwork/HonestyNetwork/wsgi.py' cannot be loaded as Python module.
[Tue Feb 02 19:39:06.059887 2021] [wsgi:error] [pid 32415:tid 140505384261376] [remote 104.195.132.229:64173] mod_wsgi (pid=32415): Exception occurred processing WSGI script '/var/www/HonestyNetwork/HonestyNetwork/wsgi.py'.
[Tue Feb 02 19:39:06.060027 2021] [wsgi:error] [pid 32415:tid 140505384261376] [remote 104.195.132.229:64173] Traceback (most recent call last):
[Tue Feb 02 19:39:06.060077 2021] [wsgi:error] [pid 32415:tid 140505384261376] [remote 104.195.132.229:64173]   File "/var/www/HonestyNetwork/HonestyNetwork/wsgi.py", line 16, in <module>
[Tue Feb 02 19:39:06.060084 2021] [wsgi:error] [pid 32415:tid 140505384261376] [remote 104.195.132.229:64173]     application = get_wsgi_application()
[Tue Feb 02 19:39:06.060092 2021] [wsgi:error] [pid 32415:tid 140505384261376] [remote 104.195.132.229:64173]   File "/usr/local/lib/python3.6/dist-packages/django/core/wsgi.py", line 12, in get_wsgi_application
[Tue Feb 02 19:39:06.060096 2021] [wsgi:error] [pid 32415:tid 140505384261376] [remote 104.195.132.229:64173]     django.setup(set_prefix=False)
[Tue Feb 02 19:39:06.060103 2021] [wsgi:error] [pid 32415:tid 140505384261376] [remote 104.195.132.229:64173]   File "/usr/local/lib/python3.6/dist-packages/django/__init__.py", line 24, in setup
[Tue Feb 02 19:39:06.060106 2021] [wsgi:error] [pid 32415:tid 140505384261376] [remote 104.195.132.229:64173]     apps.populate(settings.INSTALLED_APPS)
[Tue Feb 02 19:39:06.060112 2021] [wsgi:error] [pid 32415:tid 140505384261376] [remote 104.195.132.229:64173]   File "/usr/local/lib/python3.6/dist-packages/django/apps/registry.py", line 83, in populate
[Tue Feb 02 19:39:06.060115 2021] [wsgi:error] [pid 32415:tid 140505384261376] [remote 104.195.132.229:64173]     raise RuntimeError("populate() isn't reentrant")
[Tue Feb 02 19:39:06.060138 2021] [wsgi:error] [pid 32415:tid 140505384261376] [remote 104.195.132.229:64173] RuntimeError: populate() isn't reentrant
[Tue Feb 02 19:39:06.466593 2021] [wsgi:error] [pid 32416:tid 140505283548928] [remote 104.195.132.229:64174] mod_wsgi (pid=32416): Target WSGI script '/var/www/HonestyNetwork/HonestyNetwork/wsgi.py' cannot be loaded as Python module.
[Tue Feb 02 19:39:06.466665 2021] [wsgi:error] [pid 32416:tid 140505283548928] [remote 104.195.132.229:64174] mod_wsgi (pid=32416): Exception occurred processing WSGI script '/var/www/HonestyNetwork/HonestyNetwork/wsgi.py'.
[Tue Feb 02 19:39:06.466801 2021] [wsgi:error] [pid 32416:tid 140505283548928] [remote 104.195.132.229:64174] Traceback (most recent call last):
[Tue Feb 02 19:39:06.466842 2021] [wsgi:error] [pid 32416:tid 140505283548928] [remote 104.195.132.229:64174]   File "/var/www/HonestyNetwork/HonestyNetwork/wsgi.py", line 16, in <module>
[Tue Feb 02 19:39:06.466847 2021] [wsgi:error] [pid 32416:tid 140505283548928] [remote 104.195.132.229:64174]     application = get_wsgi_application()
[Tue Feb 02 19:39:06.466869 2021] [wsgi:error] [pid 32416:tid 140505283548928] [remote 104.195.132.229:64174]   File "/usr/local/lib/python3.6/dist-packages/django/core/wsgi.py", line 12, in get_wsgi_application
[Tue Feb 02 19:39:06.466872 2021] [wsgi:error] [pid 32416:tid 140505283548928] [remote 104.195.132.229:64174]     django.setup(set_prefix=False)
[Tue Feb 02 19:39:06.466879 2021] [wsgi:error] [pid 32416:tid 140505283548928] [remote 104.195.132.229:64174]   File "/usr/local/lib/python3.6/dist-packages/django/__init__.py", line 24, in setup
[Tue Feb 02 19:39:06.466882 2021] [wsgi:error] [pid 32416:tid 140505283548928] [remote 104.195.132.229:64174]     apps.populate(settings.INSTALLED_APPS)
[Tue Feb 02 19:39:06.466913 2021] [wsgi:error] [pid 32416:tid 140505283548928] [remote 104.195.132.229:64174]   File "/usr/local/lib/python3.6/dist-packages/django/apps/registry.py", line 83, in populate
[Tue Feb 02 19:39:06.466917 2021] [wsgi:error] [pid 32416:tid 140505283548928] [remote 104.195.132.229:64174]     raise RuntimeError("populate() isn't reentrant")
[Tue Feb 02 19:39:06.466934 2021] [wsgi:error] [pid 32416:tid 140505283548928] [remote 104.195.132.229:64174] RuntimeError: populate() isn't reentrant
[Tue Feb 02 19:39:06.823089 2021] [wsgi:error] [pid 32416:tid 140505182836480] [remote 104.195.132.229:64175] mod_wsgi (pid=32416): Target WSGI script '/var/www/HonestyNetwork/HonestyNetwork/wsgi.py' cannot be loaded as Python module.
[Tue Feb 02 19:39:06.823156 2021] [wsgi:error] [pid 32416:tid 140505182836480] [remote 104.195.132.229:64175] mod_wsgi (pid=32416): Exception occurred processing WSGI script '/var/www/HonestyNetwork/HonestyNetwork/wsgi.py'.
[Tue Feb 02 19:39:06.823312 2021] [wsgi:error] [pid 32416:tid 140505182836480] [remote 104.195.132.229:64175] Traceback (most recent call last):
[Tue Feb 02 19:39:06.823354 2021] [wsgi:error] [pid 32416:tid 140505182836480] [remote 104.195.132.229:64175]   File "/var/www/HonestyNetwork/HonestyNetwork/wsgi.py", line 16, in <module>
[Tue Feb 02 19:39:06.823359 2021] [wsgi:error] [pid 32416:tid 140505182836480] [remote 104.195.132.229:64175]     application = get_wsgi_application()
[Tue Feb 02 19:39:06.823367 2021] [wsgi:error] [pid 32416:tid 140505182836480] [remote 104.195.132.229:64175]   File "/usr/local/lib/python3.6/dist-packages/django/core/wsgi.py", line 12, in get_wsgi_application
[Tue Feb 02 19:39:06.823370 2021] [wsgi:error] [pid 32416:tid 140505182836480] [remote 104.195.132.229:64175]     django.setup(set_prefix=False)
[Tue Feb 02 19:39:06.823376 2021] [wsgi:error] [pid 32416:tid 140505182836480] [remote 104.195.132.229:64175]   File "/usr/local/lib/python3.6/dist-packages/django/__init__.py", line 24, in setup
[Tue Feb 02 19:39:06.823380 2021] [wsgi:error] [pid 32416:tid 140505182836480] [remote 104.195.132.229:64175]     apps.populate(settings.INSTALLED_APPS)
[Tue Feb 02 19:39:06.823386 2021] [wsgi:error] [pid 32416:tid 140505182836480] [remote 104.195.132.229:64175]   File "/usr/local/lib/python3.6/dist-packages/django/apps/registry.py", line 83, in populate
[Tue Feb 02 19:39:06.823389 2021] [wsgi:error] [pid 32416:tid 140505182836480] [remote 104.195.132.229:64175]     raise RuntimeError("populate() isn't reentrant")
[Tue Feb 02 19:39:06.823406 2021] [wsgi:error] [pid 32416:tid 140505182836480] [remote 104.195.132.229:64175] RuntimeError: populate() isn't reentrant
[Tue Feb 02 19:39:59.064254 2021] [wsgi:error] [pid 32415:tid 140505350690560] [remote 104.195.132.229:64226] mod_wsgi (pid=32415): Target WSGI script '/var/www/HonestyNetwork/HonestyNetwork/wsgi.py' cannot be loaded as Python module.
[Tue Feb 02 19:39:59.064366 2021] [wsgi:error] [pid 32415:tid 140505350690560] [remote 104.195.132.229:64226] mod_wsgi (pid=32415): Exception occurred processing WSGI script '/var/www/HonestyNetwork/HonestyNetwork/wsgi.py'.
[Tue Feb 02 19:39:59.064744 2021] [wsgi:error] [pid 32415:tid 140505350690560] [remote 104.195.132.229:64226] Traceback (most recent call last):
[Tue Feb 02 19:39:59.064830 2021] [wsgi:error] [pid 32415:tid 140505350690560] [remote 104.195.132.229:64226]   File "/var/www/HonestyNetwork/HonestyNetwork/wsgi.py", line 16, in <module>
[Tue Feb 02 19:39:59.064837 2021] [wsgi:error] [pid 32415:tid 140505350690560] [remote 104.195.132.229:64226]     application = get_wsgi_application()
[Tue Feb 02 19:39:59.064846 2021] [wsgi:error] [pid 32415:tid 140505350690560] [remote 104.195.132.229:64226]   File "/usr/local/lib/python3.6/dist-packages/django/core/wsgi.py", line 12, in get_wsgi_application
[Tue Feb 02 19:39:59.064849 2021] [wsgi:error] [pid 32415:tid 140505350690560] [remote 104.195.132.229:64226]     django.setup(set_prefix=False)
[Tue Feb 02 19:39:59.064856 2021] [wsgi:error] [pid 32415:tid 140505350690560] [remote 104.195.132.229:64226]   File "/usr/local/lib/python3.6/dist-packages/django/__init__.py", line 24, in setup
[Tue Feb 02 19:39:59.064859 2021] [wsgi:error] [pid 32415:tid 140505350690560] [remote 104.195.132.229:64226]     apps.populate(settings.INSTALLED_APPS)
[Tue Feb 02 19:39:59.064866 2021] [wsgi:error] [pid 32415:tid 140505350690560] [remote 104.195.132.229:64226]   File "/usr/local/lib/python3.6/dist-packages/django/apps/registry.py", line 83, in populate
[Tue Feb 02 19:39:59.064869 2021] [wsgi:error] [pid 32415:tid 140505350690560] [remote 104.195.132.229:64226]     raise RuntimeError("populate() isn't reentrant")
[Tue Feb 02 19:39:59.064887 2021] [wsgi:error] [pid 32415:tid 140505350690560] [remote 104.195.132.229:64226] RuntimeError: populate() isn't reentrant
